Workbook

Sheet 2024정산
B1: 하우스 | C1: 구분 | D1: 1월 이름 | E1: 1월 월세 | F1: TRUE | G1: 1 | H1: TRUE | I1: 2월 이름 | J1: 2월 월세 | K1: TRUE | L1: 2 | M1: TRUE | N1: 3월 이름 | O1: 3월 월세 | P1: TRUE | Q1: 3 | R1: TRUE | S1: 4월 이름 | T1: 4월 월세 | U1: TRUE | V1: 4 | W1: TRUE | X1: 5월 이름 | Y1: 5월 월세 | Z1: TRUE | AA1: 5 | AB1: TRUE | AC1: 6월 이름 | AD1: 6월 월세 | AE1: TRUE | AF1: 6 | AG1: TRUE | AH1: 7월 이름 | AI1: 7월 월세 | AJ1: TRUE | AK1: 7 | AL1: TRUE | AM1: 8월 이름 | AN1: 8월 월세 | AO1: TRUE | AP1: 8 | AQ1: TRUE | AR1: 9월 이름 | AS1: 9월 월세 | AT1: FALSE | AU1: 9 | AV1: FALSE | AW1: 10월 이름 | AX1: 10월 월세 | AY1: FALSE | AZ1: 10 | BA1: TRUE | BB1: 11월 이름 | BC1: 11월 월세 | BD1: TRUE | BE1: 11 | BF1: TRUE | BG1: 12월 이름 | BH1: 12월 월세 | BI1: TRUE | BJ1: 12 | BK1: TRUE | BL1: 1월 이름 | BM1: 1월 월세 | BN1: TRUE | BO1: 1 | BP1: TRUE | BQ1: 투자자
B2: 워너비 | C2: ='입주자'!C5 -> A-1) 1인실 우측 | D2: Maurain Sarah | E2: 610000 | F2: TRUE | G2: 80000 | H2: TRUE | I2: Maurain Sarah | J2: 610000 | K2: TRUE | L2: 80000 | M2: TRUE | N2: Maurain Sarah 3/1 Olatz Genova Zubia 3/1 | O2: =19677+640000 -> 659677 | P2: TRUE | Q2: =2581+80000 -> 82581 | R2: TRUE | S2: Olatz Genova Zubia | T2: 640000 | U2: TRUE | V2: 80000 | W2: TRUE | X2: Olatz Genova Zubia | Y2: 640000 | Z2: TRUE | AA2: 80000 | AB2: TRUE | AC2: Olatz Genova Zubia | AD2: 640000 | AE2: TRUE | AF2: 80000 | AG2: TRUE | AH2: Olatz Genova Zubia | AI2: 640000 | AJ2: TRUE | AK2: 80000 | AL2: TRUE | AM2: Olatz Genova Zubia 8/25 Giorgia Picchini 8/31 | AN2: =640000+20645 -> 660645 | AO2: TRUE | AP2: =80000+2581 -> 82581 | AQ2: TRUE | AR2: Giorgia Picchini | AS2: 640000 | AT2: TRUE | AU2: 80000 | AV2: TRUE | AW2: Giorgia Picchini | AX2: 640000 | AY2: TRUE | AZ2: 80000 | BA2: TRUE | BB2: Giorgia Picchini | BC2: 640000 | BD2: TRUE | BE2: 80000 | BF2: TRUE | BG2: Giorgia Picchini | BH2: 640000 | BI2: TRUE | BJ2: 80000 | BK2: TRUE | BL2: Giorgia Picchini | BM2: 640000 | BN2: FALSE | BO2: 80000 | BP2: FALSE | BQ2: 강연수
B3: 워너비(강남구 도산대로54길 48-15) | C3: ='입주자'!C6 -> B-1) 1인실 좌측 | D3: Ellie Jane Loong | E3: 600000 | F3: TRUE | G3: 80000 | H3: TRUE | I3: Ellie Jane Loong | J3: 600000 | K3: TRUE | L3: 80000 | M3: TRUE | N3: Ellie Jane Loong | O3: 600000 | P3: TRUE | Q3: 80000 | R3: TRUE | S3: Ellie Jane Loong | T3: 600000 | U3: TRUE | V3: 80000 | W3: TRUE | X3: Ellie Jane Loong | Y3: 600000 | Z3: TRUE | AA3: 80000 | AB3: TRUE | AC3: Ellie Jane Loong | AD3: 600000 | AE3: TRUE | AF3: 80000 | AG3: TRUE | AH3: Ellie Jane Loong | AI3: 600000 | AJ3: TRUE | AK3: 80000 | AL3: TRUE | AM3: Ellie Jane Loong | AN3: 600000 | AO3: TRUE | AP3: 80000 | AQ3: TRUE | AR3: Ellie Jane Loong | AS3: 600000 | AT3: TRUE | AU3: 80000 | AV3: TRUE | AW3: Ellie Jane Loong | AX3: 600000 | AY3: TRUE | AZ3: 80000 | BA3: TRUE | BB3: Ellie Jane Loong | BC3: 600000 | BD3: TRUE | BE3: 80000 | BF3: TRUE | BG3: Ellie Jane Loong 12/13 | BH3: 600000 | BI3: TRUE | BJ3: 80000 | BK3: TRUE | BL3: ★ | BQ3: 강연수
B4: 워너비 | C4: ='입주자'!C7 -> C-1) 2인실 오 | D4: 김정민 1/13 | E4: 275806 | F4: TRUE | G4: 49032 | H4: TRUE | I4: 김정민 | J4: 450000 | K4: TRUE | L4: 80000 | M4: TRUE | N4: 김정민 | O4: 450000 | P4: TRUE | Q4: 80000 | R4: TRUE | S4: 김정민 | T4: 450000 | U4: TRUE | V4: 80000 | W4: TRUE | X4: 김정민 | Y4: 450000 | Z4: TRUE | AA4: 80000 | AB4: TRUE | AC4: 김정민 | AD4: 450000 | AE4: TRUE | AF4: 80000 | AG4: TRUE | AH4: 김정민 | AI4: 450000 | AJ4: TRUE | AK4: 80000 | AL4: TRUE | AM4: 김정민 | AN4: 450000 | AO4: TRUE | AP4: 80000 | AQ4: TRUE | AR4: 김정민 | AS4: 450000 | AT4: TRUE | AU4: 80000 | AV4: TRUE | AW4: 김정민 | AX4: 450000 | AY4: TRUE | AZ4: 80000 | BA4: TRUE | BB4: 김정민 | BC4: 450000 | BD4: TRUE | BE4: 80000 | BF4: TRUE | BG4: 김정민 | BH4: 450000 | BI4: TRUE | BJ4: 80000 | BK4: TRUE | BL4: 김정민 | BM4: 450000 | BN4: FALSE | BO4: 80000 | BP4: FALSE | BQ4: 강연수
B5: 워너비 | C5: ='입주자'!C8 -> C-2) 2인실 왼 (창가) | D5: 유희지 (LIU QIA) | E5: 400000 | F5: TRUE | G5: 80000 | H5: TRUE | I5: 유희지 (LIU QIA) | J5: 400000 | K5: TRUE | L5: 80000 | M5: TRUE | N5: 유희지 (LIU QIA) | O5: 400000 | P5: TRUE | Q5: 80000 | R5: TRUE | S5: 유희지 (LIU QIA) | T5: 400000 | U5: TRUE | V5: 80000 | W5: TRUE | X5: 유희지 (LIU QIA) | Y5: 400000 | Z5: TRUE | AA5: 80000 | AB5: TRUE | AC5: 유희지 (LIU QIA) | AD5: 400000 | AE5: TRUE | AF5: 80000 | AG5: TRUE | AH5: 유희지 (LIU QIA) | AI5: 420000 | AJ5: TRUE | AK5: 80000 | AL5: TRUE | AM5: 유희지 (LIU QIA) | AN5: 420000 | AO5: TRUE | AP5: 80000 | AQ5: TRUE | AR5: 유희지 (LIU QIA) | AS5: 420000 | AT5: TRUE | AU5: 80000 | AV5: TRUE | AW5: 유희지 (LIU QIA) | AX5: 420000 | AY5: TRUE | AZ5: 80000 | BA5: TRUE | BB5: 유희지 (LIU QIA) | BC5: 420000 | BD5: TRUE | BE5: 80000 | BF5: TRUE | BG5: 유희지 (LIU QIA) | BH5: 420000 | BI5: TRUE | BJ5: 80000 | BK5: TRUE | BL5: 유희지 (LIU QIA) | BM5: 420000 | BN5: FALSE | BO5: 80000 | BP5: FALSE | BQ5: 강연수
C6: 합계 | E6: =SUM(E2:E5) -> 1885806 | G6: =SUM(G2:G5) -> 289032 | J6: =SUM(J2:J5) -> 2060000 | L6: =SUM(L2:L5) -> 320000 | O6: =SUM(O2:O5) -> 2109677 | Q6: =SUM(Q2:Q5) -> 322581 | T6: =SUM(T2:T5) -> 2090000 | V6: =SUM(V2:V5) -> 320000 | Y6: =SUM(Y2:Y5) -> 2090000 | AA6: =SUM(AA2:AA5) -> 320000 | AD6: =SUM(AD2:AD5) -> 2090000 | AF6: =SUM(AF2:AF5) -> 320000 | AI6: =SUM(AI2:AI5) -> 2110000 | AK6: =SUM(AK2:AK5) -> 320000 | AN6: =SUM(AN2:AN5) -> 2130645 | AP6: =SUM(AP2:AP5) -> 322581 | AS6: =SUM(AS2:AS5) -> 2110000 | AU6: =SUM(AU2:AU5) -> 320000 | AX6: =SUM(AX2:AX5) -> 2110000 | AZ6: =SUM(AZ2:AZ5) -> 320000 | BC6: =SUM(BC2:BC5) -> 2110000 | BE6: =SUM(BE2:BE5) -> 320000 | BH6: =SUM(BH2:BH5) -> 2110000 | BJ6: =SUM(BJ2:BJ5) -> 320000 | BM6: =SUM(BM2:BM5) -> 1510000 | BO6: =SUM(BO2:BO5) -> 240000 | BQ6: 강연수
C7: (고정) 월세 | E7: 950000 | J7: 950000 | O7: 950000 | T7: 950000 | Y7: 950000 | AD7: 950000 | AI7: 950000 | AN7: 950000 | AS7: 950000 | AX7: 950000 | BC7: 950000 | BH7: 950000 | BM7: 950000 | BQ7: 강연수
B8: 없음 | C8: (고정) 관리비 | BQ8: 강연수
B9: 전기 01-0845-0159 | C9: (고정) 전기 | G9: 35400 | L9: 27080 | Q9: 25400 | V9: 28610 | AA9: 25560 | AF9: 25860 | AK9: 38750 | AP9: 50670 | AU9: 51360 | AZ9: 59570 | BE9: 30900 | BJ9: 34470 | BQ9: 강연수
B10: 코원 23235558 | C10: (고정) 가스 | G10: 144800 | L10: 139920 | Q10: 120650 | V10: 86700 | AA10: 38480 | AF10: 27600 | AK10: 20930 | AP10: 15610 | AU10: 17030 | AZ10: 33710 | BE10: 84770 | BJ10: 192980 | BQ10: 강연수
B11: 건물주 | C11: (고정) 수도 | V11: 60000 | AA11: 68000 | AP11: 67000 | AZ11: 77000 | BJ11: 77000 | BQ11: 강연수
C12: (고정) 인터넷 | G12: 22000 | L12: 22000 | Q12: 22000 | V12: 22000 | AA12: 22000 | AF12: 22000 | AK12: 22000 | AP12: 22000 | AU12: 22000 | AZ12: 22000 | BE12: 22000 | BJ12: 22000 | BO12: 22000 | BQ12: 강연수
C13: (고정) 정수기 | G13: 11000 | L13: 11000 | Q13: 11000 | V13: 11000 | AA13: 11000 | AF13: 11000 | AK13: 11000 | AP13: 11000 | AU13: 11000 | AZ13: 11000 | BE13: 11000 | BJ13: 11000 | BO13: 11000 | BQ13: 강연수
C14: 그외(청소/수리/쿠팡) | G14: =SUMIFS('지출'!$G$3:$G1000,'지출'!$J$3:$J1000,G$1,'지출'!$C$3:$C1000,"워너비") -> 63550 | L14: =SUMIFS('지출'!$G$3:$G1000,'지출'!$J$3:$J1000,L$1,'지출'!$C$3:$C1000,"워너비") -> 85750 | Q14: =SUMIFS('지출'!$G$3:$G1000,'지출'!$J$3:$J1000,Q$1,'지출'!$C$3:$C1000,"워너비") -> 27020 | S14: 유학원마케팅 | T14: 3289000 | V14: =SUMIFS('지출'!$G$3:$G1000,'지출'!$J$3:$J1000,V$1,'지출'!$C$3:$C1000,"워너비") -> 0 | AA14: =SUMIFS('지출'!$G$3:$G1000,'지출'!$J$3:$J1000,AA$1,'지출'!$C$3:$C1000,"워너비") -> 0 | AF14: =SUMIFS('지출'!$G$3:$G1000,'지출'!$J$3:$J1000,AF$1,'지출'!$C$3:$C1000,"워너비") -> 0 | AK14: =SUMIFS('지출'!$G$3:$G1000,'지출'!$J$3:$J1000,AK$1,'지출'!$C$3:$C1000,"워너비") -> 0 | AP14: =SUMIFS('지출'!$G$3:$G1000,'지출'!$J$3:$J1000,AP$1,'지출'!$C$3:$C1000,"워너비") -> 0 | AU14: =SUMIFS('지출'!$G$3:$G1000,'지출'!$J$3:$J1000,AU$1,'지출'!$C$3:$C1000,"워너비") -> 0 | AZ14: =SUMIFS('지출'!$G$3:$G1000,'지출'!$J$3:$J1000,AZ$1,'지출'!$C$3:$C1000,"워너비") -> 0 | BE14: =SUMIFS('지출'!$G$3:$G1000,'지출'!$J$3:$J1000,BE$1,'지출'!$C$3:$C1000,"워너비") -> 0 | BJ14: =SUMIFS('지출'!$G$3:$G1000,'지출'!$J$3:$J1000,BJ$1,'지출'!$C$3:$C1000,"워너비") -> 0 | BO14: =SUMIFS('지출'!$G$3:$G1000,'지출'!$J$3:$J1000,BO$1,'지출'!$C$3:$C1000,"워너비") -> 63550 | BQ14: 강연수
C15: 순이익 | E15: =E6-(SUM(E7:E14)) -> 935806 | G15: =G6-(SUM(G7:G14)) -> 12282 | J15: =J6-(SUM(J7:J14)) -> 1110000 | L15: =L6-(SUM(L7:L14)) -> 34250 | O15: =O6-(SUM(O7:O14)) -> 1159677 | Q15: =Q6-(SUM(Q7:Q14)) -> 116511 | T15: =T6-(SUM(T7:T14)) -> -2149000 | V15: =V6-(SUM(V7:V14)) -> 111690 | Y15: =Y6-(SUM(Y7:Y14)) -> 1140000 | AA15: =AA6-(SUM(AA7:AA14)) -> 154960 | AD15: =AD6-(SUM(AD7:AD14)) -> 1140000 | AF15: =AF6-(SUM(AF7:AF14)) -> 233540 | AI15: =AI6-(SUM(AI7:AI14)) -> 1160000 | AK15: =AK6-(SUM(AK7:AK14)) -> 227320 | AN15: =AN6-(SUM(AN7:AN14)) -> 1180645 | AP15: =AP6-(SUM(AP7:AP14)) -> 156301 | AS15: =AS6-(SUM(AS7:AS14)) -> 1160000 | AU15: =AU6-(SUM(AU7:AU14)) -> 218610 | AX15: =AX6-(SUM(AX7:AX14)) -> 1160000 | AZ15: =AZ6-(SUM(AZ7:AZ14)) -> 116720 | BC15: =BC6-(SUM(BC7:BC14)) -> 1160000 | BE15: =BE6-(SUM(BE7:BE14)) -> 171330 | BH15: =BH6-(SUM(BH7:BH14)) -> 1160000 | BJ15: =BJ6-(SUM(BJ7:BJ14)) -> -17450 | BM15: =BM6-(SUM(BM7:BM14)) -> 560000 | BO15: =BO6-(SUM(BO7:BO14)) -> 143450 | BQ15: 강연수
B16: 0 | C16: 투자자 | E16: =E15*$B16 -> 0 | J16: =J15*$B16 -> 0 | O16: =O15*$B16 -> 0 | T16: =T15*$B16 -> 0 | Y16: =Y15*$B16 -> 0 | AD16: =AD15*$B16 -> 0 | AI16: =AI15*$B16 -> 0 | AN16: =AN15*$B16 -> 0 | AS16: =AS15*$B16 -> 0 | AX16: =AX15*$B16 -> 0 | BC16: =BC15*$B16 -> 0 | BH16: =BH15*$B16 -> 0 | BM16: =BM15*$B16 -> 0 | BQ16: 강연수
A17: =B2 -> 워너비 | B17: 1 | C17: 운영자 | E17: =E15*$B17 -> 935806 | J17: =J15*$B17 -> 1110000 | O17: =O15*$B17 -> 1159677 | T17: =T15*$B17 -> -2149000 | Y17: =Y15*$B17 -> 1140000 | AD17: =AD15*$B17 -> 1140000 | AI17: =AI15*$B17 -> 1160000 | AN17: =AN15*$B17 -> 1180645 | AS17: =AS15*$B17 -> 1160000 | AX17: =AX15*$B17 -> 1160000 | BC17: =BC15*$B17 -> 1160000 | BH17: =BH15*$B17 -> 1160000 | BM17: =BM15*$B17 -> 560000 | BQ17: 강연수
B18: 영동 | C18: A-1) 화장실 옆 | D18: Laura Mourgues De Rosa | E18: 620000 | F18: TRUE | G18: 80000 | H18: TRUE | I18: Laura Mourgues De Rosa | J18: 620000 | K18: FALSE | L18: 80000 | M18: TRUE | N18: Laura Mourgues De Rosa | O18: 620000 | P18: FALSE | Q18: 80000 | R18: TRUE | S18: Laura Mourgues De Rosa | T18: 620000 | U18: FALSE | V18: 80000 | W18: TRUE | X18: Laura Mourgues De Rosa | Y18: 620000 | Z18: FALSE | AA18: 80000 | AB18: TRUE | AC18: Laura Mourgues De Rosa 6/12 강다연(우주) 6/20 | AD18: =248000+211500 -> 459500 | AE18: FALSE | AF18: =32000+29000 -> 61000 | AG18: FALSE | AH18: 강다연(우주) | AI18: 569600 | AJ18: FALSE | AK18: 80000 | AL18: TRUE | AM18: 강다연(우주) | AN18: 569600 | AO18: FALSE | AP18: 80000 | AQ18: TRUE | AR18: 강다연(우주) | AS18: 569600 | AT18: FALSE | AU18: 80000 | AV18: TRUE | AW18: 강다연(우주) | AX18: 569600 | AY18: FALSE | AZ18: 80000 | BA18: TRUE | BB18: 강다연(우주) | BC18: 569600 | BD18: FALSE | BE18: 80000 | BF18: TRUE | BG18: 강다연(우주) | BH18: 569600 | BI18: FALSE | BJ18: 80000 | BK18: FALSE | BL18: 강다연(우주) | BM18: 569600 | BN18: FALSE | BO18: 80000 | BP18: FALSE | BQ18: 이승민
B19: 영동 | C19: B-1) 주방 앞 | D19: Floralie Roux Cecile jac | E19: 600000 | F19: FALSE | G19: 80000 | H19: TRUE | I19: Floralie Roux Cecile jac 2/25 Irene Barbieri 2/26 | J19: =560345+89655 -> 650000 | K19: FALSE | L19: =68966+11034 -> 80000 | M19: TRUE | N19: Irene Barbieri | O19: 650000 | P19: FALSE | Q19: 80000 | R19: TRUE | S19: Irene Barbieri | T19: 650000 | U19: TRUE | V19: 80000 | W19: TRUE | X19: Irene Barbieri 5/24 | Y19: 503226 | Z19: FALSE | AA19: 61935 | AB19: TRUE | AC19: 박하나 6/29 | AD19: 40000 | AE19: FALSE | AF19: 5333 | AG19: TRUE | AH19: 박하나 | AI19: 600000 | AJ19: FALSE | AK19: 80000 | AL19: TRUE | AM19: 박하나 8/3 | AN19: 600000 | AO19: FALSE | AP19: 80000 | AQ19: TRUE | AR19: Petit Fleur 9/1 | AS19: 630000 | AT19: FALSE | AU19: 80000 | AV19: TRUE | AW19: Petit Fleur | AX19: 630000 | AY19: FALSE | AZ19: 80000 | BA19: TRUE | BB19: Petit Fleur | BC19: 630000 | BD19: FALSE | BE19: 80000 | BF19: TRUE | BG19: Petit Fleur 12/17 | BH19: 630000 | BI19: FALSE | BJ19: 80000 | BK19: TRUE | BL19: 헤바Heba(우주) 1/18 | BM19: 265220 | BN19: FALSE | BO19: 36100 | BP19: FALSE | BQ19: 이승민
B20: 영동 | C20: C-1) 윗층 왼 | D20: Elena Basso | E20: 540000 | F20: FALSE | G20: 80000 | H20: TRUE | I20: Elena Basso | J20: 540000 | K20: FALSE | L20: 80000 | M20: TRUE | N20: Elena Basso | O20: 540000 | P20: FALSE | Q20: 80000 | R20: TRUE | S20: Elena Basso | T20: 540000 | U20: FALSE | V20: 80000 | W20: TRUE | X20: Elena Basso 5/22 Agathe Brillaud 5/31 | Y20: =540000+18387 -> 558387 | Z20: FALSE | AA20: =80000+2581 -> 82581 | AB20: TRUE | AC20: Agathe Brillaud | AD20: 570000 | AE20: FALSE | AF20: 80000 | AG20: TRUE | AH20: Agathe Brillaud | AI20: 570000 | AJ20: FALSE | AK20: 80000 | AL20: TRUE | AM20: Agathe Brillaud | AN20: 570000 | AO20: FALSE | AP20: 80000 | AQ20: TRUE | AR20: Agathe Brillaud 9/1 | AS20: 570000 | AT20: FALSE | AU20: 80000 | AV20: TRUE | AW20: Agathe Brillaud | AX20: 570000 | AY20: FALSE | AZ20: 80000 | BA20: TRUE | BB20: Agathe Brillaud 11/20 GUILLOTON Salomé 11/30 | BC20: =570000+19000 -> 589000 | BD20: FALSE | BE20: =80000+2667 -> 82667 | BF20: TRUE | BG20: GUILLOTON Salomé | BH20: 570000 | BI20: FALSE | BJ20: 80000 | BK20: TRUE | BL20: GUILLOTON Salomé | BM20: 570000 | BN20: FALSE | BO20: 80000 | BP20: FALSE | BQ20: 이승민
B21: 영동 | C21: D-1) 윗층 오 | D21: 이지윤(우주) 1/5 김태이(우주) 1/6 | E21: =86400+448200 -> 534600 | F21: FALSE | G21: =13000+67000 -> 80000 | H21: TRUE | I21: 이지윤(우주) 위약금 김태이(우주) | J21: =594000+534600 -> 1128600 | K21: FALSE | L21: =80000+80000 -> 160000 | M21: TRUE | N21: 김태이(우주) | O21: 534600 | P21: FALSE | Q21: 80000 | R21: TRUE | S21: 김태이(우주) | T21: 534600 | U21: FALSE | V21: 80000 | W21: TRUE | X21: 김태이(우주) | Y21: 534600 | Z21: FALSE | AA21: 80000 | AB21: TRUE | AC21: 김태이(우주) | AD21: 534600 | AE21: FALSE | AF21: 80000 | AG21: TRUE | AH21: 김태이(우주) 7/5 정다혜(우주) 7/6 | AI21: =85440+443220 -> 528660 | AJ21: FALSE | AK21: =12900+67100 -> 80000 | AL21: TRUE | AM21: 정다혜(우주) | AN21: 528660 | AO21: FALSE | AP21: 80000 | AQ21: TRUE | AR21: 정다혜(우주) | AS21: 528660 | AT21: FALSE | AU21: 80000 | AV21: TRUE | AW21: 정다혜(우주) | AX21: 528660 | AY21: FALSE | AZ21: 80000 | BA21: TRUE | BB21: 정다혜(우주) | BC21: 528660 | BD21: FALSE | BE21: 80000 | BF21: TRUE | BG21: 정다혜(우주) | BH21: 528660 | BI21: FALSE | BJ21: 80000 | BK21: FALSE | BL21: 정다혜(우주) | BM21: 528660 | BN21: FALSE | BO21: 80000 | BP21: FALSE | BQ21: 이승민
B22: 영동 | C22: E-1) 화장실 우 오른쪽 | D22: 최가인(우주) | E22: 480000 | F22: FALSE | G22: 80000 | H22: TRUE | I22: 최가인(우주) | J22: 480000 | K22: FALSE | L22: 80000 | M22: TRUE | N22: 최가인(우주) | O22: 475200 | P22: FALSE | Q22: 80000 | R22: TRUE | S22: 최가인(우주) | T22: 475200 | U22: FALSE | V22: 80000 | W22: TRUE | X22: 최가인(우주) | Y22: 475200 | Z22: FALSE | AA22: 80000 | AB22: TRUE | AC22: 최가인(우주) | AD22: 475200 | AE22: FALSE | AF22: 80000 | AG22: TRUE | AH22: 최가인(우주) | AI22: 469920 | AJ22: FALSE | AK22: 80000 | AL22: TRUE | AM22: 최가인(우주) | AN22: 469920 | AO22: FALSE | AP22: 80000 | AQ22: TRUE | AR22: 최가인(우주) 9/30 | AS22: 469920 | AT22: FALSE | AU22: 80000 | AV22: FALSE | AW22: ★ | BB22: ★ | BG22: ★ | BP22: FALSE | BQ22: 이승민
B23: 영동 | C23: E-2) 화장실 우 왼쪽 | D23: 김여김 | E23: 450000 | F23: FALSE | G23: 80000 | H23: TRUE | I23: 김여김 | J23: 450000 | K23: FALSE | L23: 80000 | M23: TRUE | N23: 김여김 | O23: 450000 | P23: FALSE | Q23: 80000 | R23: TRUE | S23: 김여김 | T23: 450000 | U23: FALSE | V23: 80000 | W23: TRUE | X23: 김여김 | Y23: 450000 | Z23: FALSE | AA23: 80000 | AB23: TRUE | AC23: 김여김 | AD23: 450000 | AE23: FALSE | AF23: 80000 | AG23: TRUE | AH23: 김여김 | AI23: 450000 | AJ23: FALSE | AK23: 80000 | AL23: TRUE | AM23: 김여김 | AN23: 450000 | AO23: FALSE | AP23: 80000 | AQ23: TRUE | AR23: 김여김 | AS23: 450000 | AT23: FALSE | AU23: 80000 | AV23: TRUE | AW23: 김여김 | AX23: 450000 | AY23: FALSE | AZ23: 80000 | BA23: TRUE | BB23: 김여김 | BC23: 450000 | BD23: FALSE | BE23: 80000 | BF23: TRUE | BG23: 김여김 | BH23: 450000 | BI23: FALSE | BJ23: 80000 | BK23: TRUE | BL23: 김여김 | BM23: 450000 | BN23: FALSE | BO23: 80000 | BP23: FALSE | BQ23: 이승민
C24: 합계 | E24: =SUM(E18:E23) -> 3224600 | G24: =SUM(G18:G23) -> 480000 | J24: =SUM(J18:J23) -> 3868600 | L24: =SUM(L18:L23) -> 560000 | O24: =SUM(O18:O23) -> 3269800 | Q24: =SUM(Q18:Q23) -> 480000 | T24: =SUM(T18:T23) -> 3269800 | V24: =SUM(V18:V23) -> 480000 | Y24: =SUM(Y18:Y23) -> 3141413 | AA24: =SUM(AA18:AA23) -> 464516 | AD24: =SUM(AD18:AD23) -> 2529300 | AF24: =SUM(AF18:AF23) -> 386333 | AI24: =SUM(AI18:AI23) -> 3188180 | AK24: =SUM(AK18:AK23) -> 480000 | AN24: =SUM(AN18:AN23) -> 3188180 | AP24: =SUM(AP18:AP23) -> 480000 | AS24: =SUM(AS18:AS23) -> 3218180 | AU24: =SUM(AU18:AU23) -> 480000 | AX24: =SUM(AX18:AX23) -> 2748260 | AZ24: =SUM(AZ18:AZ23) -> 400000 | BC24: =SUM(BC18:BC23) -> 2767260 | BE24: =SUM(BE18:BE23) -> 402667 | BH24: =SUM(BH18:BH23) -> 2748260 | BJ24: =SUM(BJ18:BJ23) -> 400000 | BM24: =SUM(BM18:BM23) -> 2383480 | BO24: =SUM(BO18:BO23) -> 356100 | BQ24: 이승민
C25: (고정) 월세 | E25: 1500000 | J25: 1500000 | O25: 1500000 | T25: 1500000 | Y25: 1500000 | AD25: 1500000 | AI25: 1500000 | AN25: 1500000 | AS25: 1500000 | AX25: 1500000 | BC25: 1500000 | BH25: 1500000 | BM25: 1500000 | BQ25: 이승민
B26: 투자자고지 | C26: (고정) 관리비/계단 | G26: 70000 | L26: 70000 | Q26: 70000 | V26: 70000 | AA26: 70000 | AF26: 70000 | AK26: 70000 | AP26: 70000 | AU26: 70000 | AZ26: 70000 | BE26: 70000 | BJ26: 70000 | BO26: 70000 | BQ26: 이승민
B27: 투자자고지 | C27: (고정) 전기 | G27: 59570 | L27: 230630 | Q27: 222360 | BQ27: 이승민
B28: 투자자고지 | C28: (고정) 가스 | G28: 262890 | L28: 127220 | Q28: 102090 | BQ28: 이승민
B29: 투자자고지 | C29: (고정) 수도 | G29: 0 | L29: 30912 | Q29: 0 | BQ29: 이승민
B30: 투자자고지 | C30: (고정) 인터넷 | G30: 22000 | L30: 22000 | Q30: 22000 | V30: 22000 | AA30: 22000 | AF30: 22000 | AK30: 22000 | AP30: 22000 | AU30: 22000 | AZ30: 22000 | BE30: 22000 | BJ30: 22000 | BO30: 22000 | BQ30: 이승민
B31: 투자자고지 | C31: (고정) 정수기 | G31: 19900 | L31: 19900 | Q31: 19900 | V31: 19900 | AA31: 19900 | AF31: 19900 | AK31: 19900 | AP31: 19900 | AU31: 19900 | AZ31: 19900 | BE31: 19900 | BJ31: 19900 | BO31: 19900 | BQ31: 이승민
C32: 그외(청소/수리/쿠팡) | G32: =SUMIFS('지출'!$G$3:$G1000,'지출'!$J$3:$J1000,G$1,'지출'!$C$3:$C1000,"영동") -> 174360 | L32: =SUMIFS('지출'!$G$3:$G1000,'지출'!$J$3:$J1000,L$1,'지출'!$C$3:$C1000,"영동") -> 50000 | Q32: =SUMIFS('지출'!$G$3:$G1000,'지출'!$J$3:$J1000,Q$1,'지출'!$C$3:$C1000,"영동") -> 124500 | V32: =SUMIFS('지출'!$G$3:$G1000,'지출'!$J$3:$J1000,V$1,'지출'!$C$3:$C1000,"영동") -> 0 | AA32: =SUMIFS('지출'!$G$3:$G1000,'지출'!$J$3:$J1000,AA$1,'지출'!$C$3:$C1000,"영동") -> 0 | AF32: =SUMIFS('지출'!$G$3:$G1000,'지출'!$J$3:$J1000,AF$1,'지출'!$C$3:$C1000,"영동") -> 0 | AK32: =SUMIFS('지출'!$G$3:$G1000,'지출'!$J$3:$J1000,AK$1,'지출'!$C$3:$C1000,"영동") -> 0 | AP32: =SUMIFS('지출'!$G$3:$G1000,'지출'!$J$3:$J1000,AP$1,'지출'!$C$3:$C1000,"영동") -> 0 | AU32: =SUMIFS('지출'!$G$3:$G1000,'지출'!$J$3:$J1000,AU$1,'지출'!$C$3:$C1000,"영동") -> 0 | AZ32: =SUMIFS('지출'!$G$3:$G1000,'지출'!$J$3:$J1000,AZ$1,'지출'!$C$3:$C1000,"영동") -> 0 | BE32: =SUMIFS('지출'!$G$3:$G1000,'지출'!$J$3:$J1000,BE$1,'지출'!$C$3:$C1000,"영동") -> 0 | BJ32: =SUMIFS('지출'!$G$3:$G1000,'지출'!$J$3:$J1000,BJ$1,'지출'!$C$3:$C1000,"영동") -> 0 | BO32: =SUMIFS('지출'!$G$3:$G1000,'지출'!$J$3:$J1000,BO$1,'지출'!$C$3:$C1000,"영동") -> 174360 | BQ32: 이승민
C33: 순이익 | E33: =E24-(SUM(E25:E32)) -> 1724600 | G33: =G24-(SUM(G25:G32)) -> -128720 | J33: =J24-(SUM(J25:J32)) -> 2368600 | L33: =L24-(SUM(L25:L32)) -> 9338 | O33: =O24-(SUM(O25:O32)) -> 1769800 | Q33: =Q24-(SUM(Q25:Q32)) -> -80850 | T33: =T24-(SUM(T25:T32)) -> 1769800 | V33: =V24-(SUM(V25:V32)) -> 368100 | Y33: =Y24-(SUM(Y25:Y32)) -> 1641413 | AA33: =AA24-(SUM(AA25:AA32)) -> 352616 | AD33: =AD24-(SUM(AD25:AD32)) -> 1029300 | AF33: =AF24-(SUM(AF25:AF32)) -> 274433 | AI33: =AI24-(SUM(AI25:AI32)) -> 1688180 | AK33: =AK24-(SUM(AK25:AK32)) -> 368100 | AN33: =AN24-(SUM(AN25:AN32)) -> 1688180 | AP33: =AP24-(SUM(AP25:AP32)) -> 368100 | AS33: =AS24-(SUM(AS25:AS32)) -> 1718180 | AU33: =AU24-(SUM(AU25:AU32)) -> 368100 | AX33: =AX24-(SUM(AX25:AX32)) -> 1248260 | AZ33: =AZ24-(SUM(AZ25:AZ32)) -> 288100 | BC33: =BC24-(SUM(BC25:BC32)) -> 1267260 | BE33: =BE24-(SUM(BE25:BE32)) -> 290767 | BH33: =BH24-(SUM(BH25:BH32)) -> 1248260 | BJ33: =BJ24-(SUM(BJ25:BJ32)) -> 288100 | BM33: =BM24-(SUM(BM25:BM32)) -> 883480 | BO33: =BO24-(SUM(BO25:BO32)) -> 69840 | BQ33: 이승민
B34: 0.7 | C34: 투자자 | E34: =E33*$B34 -> 1207220 | J34: =J33*$B34 -> 1658020 | O34: =O33*$B34 -> 1238860 | T34: =T33*$B34 -> 1238860 | Y34: =Y33*$B34 -> 1148989.1 | AD34: =AD33*$B34 -> 720510 | AI34: =AI33*$B34 -> 1181726 | AN34: =AN33*$B34 -> 1181726 | AS34: =AS33*$B34 -> 1202726 | AX34: =AX33*$B34 -> 873782 | BC34: =BC33*$B34 -> 887082 | BH34: =BH33*$B34 -> 873782 | BM34: =BM33*$B34 -> 618436 | BQ34: 이승민
A35: =B18 -> 영동 | B35: 0.3 | C35: 운영자 | E35: =E33*$B35 -> 517380 | J35: =J33*$B35 -> 710580 | O35: =O33*$B35 -> 530940 | T35: =T33*$B35 -> 530940 | Y35: =Y33*$B35 -> 492423.9 | AD35: =AD33*$B35 -> 308790 | AI35: =AI33*$B35 -> 506454 | AN35: =AN33*$B35 -> 506454 | AS35: =AS33*$B35 -> 515454 | AX35: =AX33*$B35 -> 374478 | BC35: =BC33*$B35 -> 380178 | BH35: =BH33*$B35 -> 374478 | BM35: =BM33*$B35 -> 265044 | BQ35: 이승민
B36: 삼중 | C36: A-1) 미닫이문 오 | D36: Sabrina AHMED | E36: 600000 | F36: FALSE | G36: 80000 | H36: TRUE | I36: Sabrina AHMED 2/29 | J36: 600000 | K36: FALSE | L36: 80000 | M36: TRUE | N36: 유진 3/1 | O36: 600000 | P36: FALSE | Q36: =80000+70000 -> 150000 | R36: TRUE | S36: 유진 | T36: 600000 | U36: FALSE | V36: 80000 | W36: TRUE | X36: 유진 | Y36: 600000 | Z36: FALSE | AA36: 80000 | AB36: TRUE | AC36: 유진 | AD36: 600000 | AE36: FALSE | AF36: 80000 | AG36: TRUE | AH36: 유진 | AI36: 600000 | AJ36: FALSE | AK36: 80000 | AL36: TRUE | AM36: 유진 | AN36: 600000 | AO36: FALSE | AP36: 80000 | AQ36: TRUE | AR36: 유진 9/1 | AS36: 600000 | AT36: FALSE | AU36: 80000 | AV36: TRUE | AW36: 유진 | AX36: 600000 | AY36: FALSE | AZ36: 80000 | BA36: TRUE | BB36: 유진 | BC36: 600000 | BD36: FALSE | BE36: 80000 | BF36: TRUE | BG36: 유진 | BH36: 600000 | BI36: FALSE | BJ36: 80000 | BK36: TRUE | BL36: 유진 | BM36: 600000 | BN36: FALSE | BO36: 80000 | BP36: FALSE | BQ36: 이승민
B37: 삼중 | C37: B-1) 거실 오른쪽 | D37: 최예진 | E37: 550000 | F37: FALSE | G37: 80000 | H37: TRUE | I37: 최예진 | J37: 550000 | K37: FALSE | L37: 80000 | M37: TRUE | N37: 최예진 | O37: 550000 | P37: FALSE | Q37: =80000+70000 -> 150000 | R37: TRUE | S37: 최예진 | T37: 550000 | U37: FALSE | V37: 80000 | W37: TRUE | X37: 최예진 | Y37: 550000 | Z37: FALSE | AA37: 80000 | AB37: TRUE | AC37: 최예진 | AD37: 550000 | AE37: FALSE | AF37: 80000 | AG37: TRUE | AH37: 최예진 | AI37: 550000 | AJ37: FALSE | AK37: 80000 | AL37: TRUE | AM37: 최예진 | AN37: 550000 | AO37: FALSE | AP37: 80000 | AQ37: TRUE | AR37: 최예진 | AS37: 550000 | AT37: FALSE | AU37: 80000 | AV37: TRUE | AW37: 최예진 | AX37: 550000 | AY37: FALSE | AZ37: 80000 | BA37: TRUE | BB37: 최예진 | BC37: 550000 | BD37: FALSE | BE37: 80000 | BF37: TRUE | BG37: 최예진 | BH37: 550000 | BI37: FALSE | BJ37: 80000 | BK37: TRUE | BL37: 최예진 | BM37: 550000 | BN37: FALSE | BO37: 80000 | BP37: FALSE | BQ37: 이승민
B38: 삼중 | C38: C-1) 주방 맞은편 | D38: 유진 | E38: 570000 | F38: FALSE | G38: 80000 | H38: TRUE | I38: 유진 2/29 Florance Herren 2/29 | J38: =570000+20690 -> 590690 | K38: FALSE | L38: =80000+2759 -> 82759 | M38: TRUE | N38: Florance Herren | O38: 600000 | P38: FALSE | Q38: =80000+70000 -> 150000 | R38: TRUE | S38: Florance Herren | T38: 600000 | U38: FALSE | V38: 80000 | W38: TRUE | X38: Florance Herren | Y38: 600000 | Z38: FALSE | AA38: 80000 | AB38: TRUE | AC38: Florance Herren | AD38: 600000 | AE38: FALSE | AF38: 80000 | AG38: TRUE | AH38: Florance Herren | AI38: 600000 | AJ38: FALSE | AK38: 80000 | AL38: TRUE | AM38: Florance Herren 8/19 박하나 계약취소 위약금 황다원 8/25 | AN38: =367742+500000+110323+18387 -> 996452 | AO38: FALSE | AP38: =49032+15484+2581 -> 67097 | AQ38: TRUE | AR38: 황다원 | AS38: 570000 | AT38: FALSE | AU38: 80000 | AV38: TRUE | AW38: 황다원 | AX38: 570000 | AY38: FALSE | AZ38: 80000 | BA38: TRUE | BB38: 황다원 | BC38: 570000 | BD38: FALSE | BE38: 80000 | BF38: TRUE | BG38: 황다원 | BH38: 570000 | BI38: FALSE | BJ38: 80000 | BK38: TRUE | BL38: 황다원 | BM38: 570000 | BN38: FALSE | BO38: 80000 | BP38: FALSE | BQ38: 이승민
B39: 삼중 | C39: D-1) 주방 옆 문쪽 | D39: Sonia Hila | E39: 530000 | F39: FALSE | G39: 80000 | H39: TRUE | I39: Sonia Hila 2/21 | J39: 383793 | K39: FALSE | L39: 57931 | M39: TRUE | N39: Amina Elisabeth Deutz 3/15 | O39: 263226 | P39: FALSE | Q39: 43871 | R39: TRUE | S39: Amina Elisabeth Deutz 4/29 | T39: 480000 | U39: FALSE | V39: 80000 | W39: TRUE | X39: Amina Elisabeth Deutz | Y39: 480000 | Z39: FALSE | AA39: 80000 | AB39: TRUE | AC39: Amina Elisabeth Deutz 위약금 1 | AD39: 480000 | AE39: FALSE | AF39: 80000 | AG39: TRUE | AH39: 김라엘 7/25 | AI39: 100000 | AJ39: TRUE | AK39: 20000 | AL39: TRUE | AM39: 김라엘 8/19 | AN39: 300000 | AO39: TRUE | AP39: 60000 | AQ39: TRUE | AR39: Demi Klinkhamer 9/15 | AS39: 256000 | AT39: FALSE | AU39: 42667 | AV39: TRUE | AW39: Demi Klinkhamer | AX39: 480000 | AY39: FALSE | AZ39: 80000 | BA39: TRUE | BB39: Demi Klinkhamer | BC39: 480000 | BD39: FALSE | BE39: 80000 | BF39: TRUE | BG39: Demi Klinkhamer 12/17 | BH39: =480000 -> 480000 | BI39: FALSE | BJ39: =80000 -> 80000 | BK39: TRUE | BL39: Demi Klinkhamer 위약금 | BM39: =480000 -> 480000 | BN39: FALSE | BO39: =80000 -> 80000 | BP39: TRUE | BQ39: 이승민
B40: 삼중 | C40: D-2) 주방 옆 안쪽 | D40: Aldana | E40: 500000 | F40: FALSE | G40: 80000 | H40: TRUE | I40: Aldana 2/24 | J40: 413793 | K40: FALSE | L40: 66207 | M40: TRUE | N40: Maja Aengenvoort 3/15 | O40: 263226 | P40: FALSE | Q40: 43871 | R40: TRUE | S40: Maja Aengenvoort | T40: 480000 | U40: FALSE | V40: 80000 | W40: TRUE | X40: Maja Aengenvoort | Y40: 480000 | Z40: FALSE | AA40: 80000 | AB40: TRUE | AC40: Maja Aengenvoort 6/12 | AD40: 480000 | AE40: FALSE | AF40: 80000 | AG40: TRUE | AH40: ★ | AM40: 김난영 8/1~19 Jessica 8/19 | AN40: =300000+201290 -> 501290 | AO40: FALSE | AP40: =80000+33548 -> 113548 | AQ40: TRUE | AR40: Jessica | AS40: 480000 | AT40: FALSE | AU40: 80000 | AV40: TRUE | AW40: Jessica | AX40: 480000 | AY40: FALSE | AZ40: 80000 | BA40: TRUE | BB40: Jessica | BC40: 480000 | BD40: FALSE | BE40: 80000 | BF40: TRUE | BG40: Jessica 12/17 | BH40: 480000 | BI40: FALSE | BJ40: 80000 | BK40: TRUE | BL40: Jessica 위약금1 | BM40: 480000 | BN40: FALSE | BO40: 80000 | BP40: TRUE | BQ40: 이승민
...

Sheet 입주자
A1: =(C3-C2)+1 -> 11 | B1: 이름 : | C1: 조경주 | D1: 첫달 월세 | E1: =(A2/C3)*(C3-C2+1) -> 131290.32 | F1: 퇴실 월세 | G1: =(A2/C3)*C2 -> 250645.16 | H1: 이승민,공진 | I1: 외국인 계좌 | J1: Kakao bank 3333-12-6297317 이승민 Lee Seungmin | K1: Phone : 010-7588-5201, | L1: Birth : 1974-Nov-04, | M1: email : hooniga2@naver.com | O1: 541667 | P1: =A2-G1 -> 119354.84
A2: =VLOOKUP(C1,E5:P494,9,0) -> 370000 | B2: 입주일자 : | C2: 21 | D2: 첫달 관리비 | E2: =(A3/C3)*A1 -> 35483.871 | F2: 퇴실 관리비 | G2: =(A3/C3)*C2 -> 67741.935 | H2: 회기하우스 | I2: 관리비계좌 | J2: 카카오뱅크 박미선 3333-1011-09421 | N2: =440000/31 -> 14193.548 | O2: =O1+G1 -> 792312.16 | P2: =A3-G2 -> 32258.065
A3: =VLOOKUP($C$1,E5:P494,10,0) -> 100000 | B3: 한달 기준일 : | C3: 31 | D3: 잔금 | E3: =VLOOKUP(C1,E5:Y494,20,0)+E1 -> 1631290.3 | F3: =A2/C3 -> 11935.484 | G3: =F3*20 -> 238709.68 | H3: =A3/C3 -> 3225.8065 | I3: ★ | J3: =F3*31 -> 370000 | K3: =3333*18 -> 59994 | M3: =62+6.2 -> 68.2 | N3: =100000/31 -> 3225.8065
A4: 지역 | B4: 하우스 | C4: 자리 | D4: 구분 | E4: 계약자 | F4: 계약시작 | G4: 계약종료 | H4: 추가사항 | I4: 공실 | J4: 보증금 | K4: 6개월 가격 | L4: 할인 | M4: 월세 | N4: 관리비 | O4: 생년월일 | P4: 연락처 | Q4: 주소 | R4: 하우스 | S4: 자리 | T4: 투자자 | U4: 계좌 | V4: 연락처 | W4: 생년월일 | X4: 잔금
A5: 강남구 | B5: 워너비 | C5: A-1) 1인실 우측 | D5: 1인실 | E5: 柯吟 周 Ko Yin Zhou (엔코) | F5: 46081 | G5: 46195 | J5: 2000000 | K5: 620000 | L5: -60000 | M5: =K5-L5 -> 680000 | N5: 100000 | P5: zke86090@gmail.com | Q5: 서울시 강남구 논현동 104-13 201호 | R5: 워너비하우스 | S5: =C5 -> A-1) 1인실 우측 | T5: 강연수 | U5: 3333-08-6259-701 카카오뱅크 강연수 | V5: 010-9207-2588 | W5: 747-14-01518 | X5: =J5-500000 -> 1500000 | Y5: 아띠
A6: 강남구 | B6: 워너비 | C6: B-1) 1인실 좌측 | D6: 1인실 | E6: RAMADANTI ALFIYYAH ZAHRA 정아라 | F6: 46082 | G6: 46173 | H6: A룸 이동희망 | J6: 2000000 | K6: 590000 | L6: 0 | M6: =K6-L6 -> 590000 | N6: 100000 | P6: florentina.roiciu@gmail.com | Q6: 서울시 강남구 논현동 104-13 201호 | R6: 워너비하우스 | S6: =C6 -> B-1) 1인실 좌측 | T6: 강연수 | U6: 3333-08-6259-701 카카오뱅크 강연수 | V6: 010-9207-2588 | W6: 747-14-01518 | X6: =J6-500000 -> 1500000 | Y6: 아띠
A7: 강남구 | B7: 워너비 | C7: C-1) 2인실 오 | D7: 2인실 | E7: 유은선 | F7: 46113 | G7: 46142 | H7: 정상퇴실 4.30 | I7: 공실예정 | J7: 2000000 | K7: 470000 | L7: 0 | M7: =K7-L7 -> 470000 | N7: 100000 | O7: 070501- | P7: 010-7488-6879 | Q7: 서울시 강남구 논현동 104-13 201호 | R7: 워너비하우스 | S7: =C7 -> C-1) 2인실 오 | T7: 강연수 | U7: 3333-08-6259-701 카카오뱅크 강연수 | V7: 010-9207-2588 | W7: 747-14-01518 | X7: =J7-500000 -> 1500000 | Y7: 아띠
A8: 강남구 | B8: 워너비 | C8: C-2) 2인실 왼 (창가) | D8: 2인실 | E8: 한찬유 | F8: 45962 | G8: 46142 | H8: 정상퇴실 4.30 | I8: 공실예정 | J8: 2000000 | K8: 470000 | L8: 0 | M8: =K8-L8 -> 470000 | N8: 100000 | O8: 970604- | P8: 010-6765-6443 | Q8: 서울시 강남구 논현동 104-13 201호 | R8: 워너비하우스 | S8: =C8 -> C-2) 2인실 왼 (창가) | T8: 강연수 | U8: 3333-08-6259-701 카카오뱅크 강연수 | V8: 010-9207-2588 | W8: 747-14-01518 | X8: =J8-500000 -> 1500000 | Y8: 아띠
A9: 강남구 | B9: 영동 | C9: A-1) 화장실 옆 | D9: 1인실 | E9: Maïa Redonnet(엔코) | F9: 45894 | G9: 46173 | J9: 2000000 | K9: 650000 | L9: -50000 | M9: =K9-L9 -> 700000 | N9: 100000 | P9: redonnet.maia@gmail.com | Q9: 서울시 강남구 논현동139-18 3층 | R9: 영동하우스 | S9: =C9 -> A-1) 화장실 옆 | T9: 이승민 | U9: 신협 저축은행 이승민 132 099 791064 | V9: 010-7588-5201 | W9: 1974-11-04 | X9: =J9-500000 -> 1500000 | Y9: 이승민 | Z9: 엔코
A10: 강남구 | B10: 영동 | C10: B-1) 주방 앞 | D10: 1인실 | E10: Maria Katharina Henneken(엔코) | F10: 46081 | G10: 46188 | J10: 2000000 | K10: 620000 | L10: -80000 | M10: =K10-L10 -> 700000 | N10: 100000 | P10: makatharinah@gmail.com | Q10: 서울시 강남구 논현동139-18 3층 | R10: 영동하우스 | S10: =C10 -> B-1) 주방 앞 | T10: 이승민 | U10: Kakao bank 3333-12-6297317 이승민 Lee Seungmin | V10: 010-7588-5201 | W10: 1974-11-04 | X10: =J10-500000 -> 1500000 | Y10: 이승민 | Z10: 우주
A11: 강남구 | B11: 영동 | C11: C-1) 윗층 왼쪽 | D11: 1인실 | E11: Adia Arthur(엔코) | F11: 46031 | G11: 46200 | J11: 2000000 | K11: 540000 | L11: 0 | M11: =K11-L11 -> 540000 | N11: 100000 | O11: 941127- | P11: 010-9429-9347 | Q11: 서울시 강남구 논현동139-18 3층 | R11: 영동하우스 | S11: =C11 -> C-1) 윗층 왼쪽 | T11: 이승민 | U11: 신협 저축은행 이승민 132 099 791064 | V11: 010-7588-5201 | W11: 1974-11-04 | X11: =J11-500000 -> 1500000 | Y11: 이승민 | Z11: 엔코
A12: 강남구 | B12: 영동 | C12: D-1) 윗층 오 | D12: 1인실 | E12: 정다혜(우주) | F12: 46023 | G12: 46387 | J12: 2000000 | K12: 540000 | L12: -30000 | M12: =K12-L12 -> 570000 | N12: 100000 | O12: 870827- | P12: 010-8682-2307 | Q12: 서울시 강남구 논현동139-18 3층 | R12: 영동하우스 | S12: =C12 -> D-1) 윗층 오 | T12: 이승민 | U12: 신협 저축은행 이승민 132 099 791064 | V12: 010-7588-5201 | W12: 1974-11-04 | X12: =J12-500000 -> 1500000 | Y12: 이승민 | Z12: 우주
A13: 강남구 | B13: 영동 | C13: E-1) 화장실 우 오른쪽 | D13: 2인실 | E13: 즉시입주 | I13: 공실 | J13: 2000000 | K13: 480000 | L13: 0 | M13: =K13-L13 -> 480000 | N13: 100000 | Q13: 서울시 강남구 논현동139-18 3층 | R13: 영동하우스 | S13: =C13 -> E-1) 화장실 우 오른쪽 | T13: 이승민 | U13: 신협 저축은행 이승민 132 099 791064 | V13: 010-7588-5201 | W13: 1974-11-04 | X13: =J13-500000 -> 1500000 | Y13: 이승민 | Z13: 고고
A14: 강남구 | B14: 영동 | C14: E-2) 화장실 우 왼쪽 | D14: 2인실 | E14: 즉시입주 | I14: 공실 | J14: 2000000 | K14: 480000 | L14: 0 | M14: =K14-L14 -> 480000 | N14: 100000 | Q14: 서울시 강남구 논현동139-18 3층 | R14: 영동하우스 | S14: =C14 -> E-2) 화장실 우 왼쪽 | T14: 이승민 | U14: 신협 저축은행 이승민 132 099 791064 | V14: 010-7588-5201 | W14: 1974-11-04 | X14: =J14-500000 -> 1500000 | Y14: 이승민 | Z14: 고고
A15: 강남구 | B15: 삼중 | C15: A-1) 미닫이문 오 | D15: 1인실 | E15: 최예진 | F15: 46054 | G15: 46418 | J15: 2000000 | K15: 620000 | L15: 70000 | M15: =K15-L15 -> 550000 | N15: 100000 | O15: 040521- | P15: 010-5695-7033 | Q15: 서울시 강남구 봉은사로 78길 17 3층 | R15: 삼중하우스 | S15: =C15 -> A-1) 미닫이문 오 | T15: 이승민 | U15: 저축은행(사이다뱅크) 02810-13-9166591 이승민 | V15: 010-7588-5201 | W15: 1974-11-04 | X15: =J15-500000 -> 1500000 | Y15: 이승민
A16: 강남구 | B16: 삼중 | C16: B-1) 거실 오른쪽 | D16: 1인실 | E16: 차지수 | F16: 46102 | G16: 46466 | J16: 2000000 | K16: 620000 | L16: 50000 | M16: =K16-L16 -> 570000 | N16: 100000 | O16: 010312- | P16: 010-2719-1484 | Q16: 서울시 강남구 봉은사로 78길 17 3층 | R16: 삼중하우스 | S16: =C16 -> B-1) 거실 오른쪽 | T16: 이승민 | U16: 저축은행(사이다뱅크) 02810-13-9166591 이승민 | V16: 010-7588-5201 | W16: 1974-11-04 | X16: =J16-500000 -> 1500000 | Y16: 이승민
A17: 강남구 | B17: 삼중 | C17: C-1) 주방 맞은편 | D17: 1인실 | E17: 김유미나 | F17: 46089 | G17: 46180 | J17: 2000000 | K17: 590000 | L17: -30000 | M17: =K17-L17 -> 620000 | N17: 100000 | P17: yuminakim@gmail.com | Q17: 서울시 강남구 봉은사로 78길 17 3층 | R17: 삼중하우스 | S17: =C17 -> C-1) 주방 맞은편 | T17: 이승민 | U17: 저축은행(사이다뱅크) 02810-13-9166591 이승민 | V17: 010-7588-5201 | W17: 1974-11-04 | X17: =J17-500000 -> 1500000 | Y17: 이승민 | Z17: 엔코
A18: 강남구 | B18: 삼중 | C18: D-1) 주방 옆 문쪽 | D18: 2인실 | E18: Dafne Carolina Castillo Normandía(고고) | F18: 46096 | G18: 46187 | J18: 2000000 | K18: 500000 | L18: -30000 | M18: =K18-L18 -> 530000 | N18: 100000 | O18: N19900233 | P18: dccn7@yahoo.com | Q18: 서울시 강남구 봉은사로 78길 17 3층 | R18: 삼중하우스 | S18: =C18 -> D-1) 주방 옆 문쪽 | T18: 이승민 | U18: Kakao bank 3333-12-6297317 이승민 Lee Seungmin | V18: 010-7588-5201 | W18: 1974-11-04 | X18: =J18-500000 -> 1500000 | Y18: 이승민
A19: 강남구 | B19: 삼중 | C19: D-2) 주방 옆 안쪽 | D19: 2인실 | E19: Gregoratti Greta(엔코) | F19: 45954 | G19: 46319 | J19: 2000000 | K19: 500000 | L19: -50000 | M19: =K19-L19 -> 550000 | N19: 100000 | Q19: 서울시 강남구 봉은사로 78길 17 3층 | R19: 삼중하우스 | S19: =C19 -> D-2) 주방 옆 안쪽 | T19: 이승민 | U19: 저축은행(사이다뱅크) 02810-13-9166591 이승민 | V19: 010-7588-5201 | W19: 1974-11-04 | X19: =J19-500000 -> 1500000 | Y19: 이승민 | Z19: 엔코
A20: 강남구 | B20: 삼중 | C20: E-1) 입구방 왼쪽 | D20: 2인실 | E20: 나선일 | F20: 46116 | G20: 46477 | J20: 2000000 | K20: 470000 | L20: 50000 | M20: =K20-L20 -> 420000 | N20: 100000 | O20: 960503- | P20: 010-2731-1312 | Q20: 서울시 강남구 봉은사로 78길 17 3층 | R20: 삼중하우스 | S20: =C20 -> E-1) 입구방 왼쪽 | T20: 이승민 | U20: 저축은행(사이다뱅크) 02810-13-9166591 이승민 | V20: 010-7588-5201 | W20: 1974-11-04 | X20: =J20-500000 -> 1500000 | Y20: 이승민 | Z20: 고고
A21: 강남구 | B21: 삼중 | C21: E-2) 입구방 오른쪽 | D21: 2인실 | E21: Caterina Ventrella(고고) | F21: 45997 | G21: 46173 | J21: 2000000 | K21: 470000 | L21: -30000 | M21: =K21-L21 -> 500000 | N21: 100000 | O21: YC2595471 | P21: caterinaventrella98@gmail.com | Q21: 서울시 강남구 봉은사로 78길 17 3층 | R21: 삼중하우스 | S21: =C21 -> E-2) 입구방 오른쪽 | T21: 이승민 | U21: 저축은행(사이다뱅크) 02810-13-9166591 이승민 | V21: 010-7588-5201 | W21: 1974-11-04 | X21: =J21-500000 -> 1500000 | Y21: 이승민
A22: 강남구 | B22: 삼중 | C22: F-1) 윗층방 왼쪽 | D22: 2인실 | E22: 즉시입주 | I22: 공실 | J22: 1000000 | K22: 490000 | L22: 0 | M22: =K22-L22 -> 490000 | N22: 100000 | Q22: 서울시 강남구 봉은사로 78길 17 3층 | R22: 삼중하우스 | S22: F-2) 윗층방 오른쪽 | T22: 이승민 | U22: 저축은행(사이다뱅크) 02810-13-9166591 이승민 | V22: 010-7588-5201 | W22: 1974-11-04 | X22: 500000 | Y22: 이승민
A23: 강남구 | B23: 삼중 | C23: F-2) 윗층방 오른쪽 | D23: 2인실 | E23: 즉시입주 | I23: 공실 | J23: 1000000 | K23: 490000 | L23: 40000 | M23: =K23-L23 -> 450000 | N23: 80000 | O23: 860901- | P23: 010-2694-7990 | Q23: 서울시 강남구 봉은사로 78길 17 3층 | R23: 삼중하우스 | S23: =C23 -> F-2) 윗층방 오른쪽 | T23: 이승민 | U23: 저축은행(사이다뱅크) 02810-13-9166591 이승민 | V23: 010-7588-5201 | W23: 1974-11-04 | X23: =J23-500000 -> 500000 | Y23: 이승민
A24: 강남구 | B24: 반포 | C24: A-1) (화) 왼 | D24: 1인실 | E24: 서영은 | F24: 46054 | G24: 46234 | J24: 2000000 | K24: 650000 | L24: 0 | M24: =K24-L24 -> 650000 | N24: 100000 | O24: 20DF1917 | P24: party.camille@orange.fr | Q24: 서울시 서초구 사평대로53길 97 유진빌라 C동 3층 | R24: 반포하우스 | S24: =C24 -> A-1) (화) 왼 | T24: 이승민 | U24: 국민 이승민 782702-04-131415 | V24: 010-7588-5201 | W24: 1974-11-04 | X24: =J24-500000 -> 1500000 | Y24: 이승민
A25: 강남구 | B25: 반포 | C25: B-1) (화) 오 | D25: 1인실 | E25: 이하림 | F25: 46159 | G25: 46356 | H25: 조은 중도퇴실 5.17 | J25: 2000000 | K25: 620000 | L25: 0 | M25: =K25-L25 -> 620000 | N25: 100000 | O25: 930506- | P25: 010-3951-1170 | Q25: 서울시 서초구 사평대로53길 97 유진빌라 C동 3층 | R25: 반포하우스 | S25: =C25 -> B-1) (화) 오 | T25: 이승민 | U25: 국민 이승민 782702-04-131415 | V25: 010-7588-5201 | W25: 1974-11-04 | X25: =J25-500000 -> 1500000 | Y25: 이승민
A26: 강남구 | B26: 반포 | C26: C-1) 입구왼 | D26: 1인실 | E26: 서민지 | F26: 45870 | G26: 46234 | J26: 2000000 | K26: 600000 | L26: 30000 | M26: =K26-L26 -> 570000 | N26: 100000 | O26: 010316- | P26: 010-2821-6195 | Q26: 서울시 서초구 사평대로53길 97 유진빌라 C동 3층 | R26: 반포하우스 | S26: =C26 -> C-1) 입구왼 | T26: 이승민 | U26: 국민 이승민 782702-04-131415 | V26: 010-7588-5201 | W26: 1974-11-04 | X26: =J26-500000 -> 1500000 | Y26: 이승민
A27: 강남구 | B27: 반포 | C27: D-1) 거실 가벽 | D27: 1인실 | E27: 김여원 | F27: 46032 | G27: 46212 | J27: 2000000 | K27: 550000 | L27: 0 | M27: =K27-L27 -> 550000 | N27: 100000 | O27: 940707- | P27: 010-7521-7872 | Q27: 서울시 서초구 사평대로53길 97 유진빌라 C동 3층 | R27: 반포하우스 | S27: =C27 -> D-1) 거실 가벽 | T27: 이승민 | U27: 국민 이승민 782702-04-131415 | V27: 010-7588-5201 | W27: 1974-11-04 | X27: =J27-500000 -> 1500000 | Y27: 이승민 | Z27: 엔코
A28: 강남구 | B28: 반포 | C28: E-1) (거실화) 왼 | D28: 2인실 | E28: 즉시입주 | I28: 공실 | J28: 2000000 | K28: 480000 | L28: 0 | M28: =K28-L28 -> 480000 | N28: 100000 | Q28: 서울시 서초구 사평대로53길 97 유진빌라 C동 3층 | R28: 반포하우스 | S28: =C28 -> E-1) (거실화) 왼 | T28: 이승민 | U28: 국민 이승민 782702-04-131415 | V28: 010-7588-5201 | W28: 1974-11-04 | X28: =J28-500000 -> 1500000 | Y28: 이승민 | Z28: 엔코
A29: 강남구 | B29: 반포 | C29: F-1) (거실화) 오 | D29: 2인실 | E29: 즉시입주 | I29: 공실 | J29: 2000000 | K29: 480000 | L29: -20000 | M29: =K29-L29 -> 500000 | N29: 100000 | Q29: 서울시 서초구 사평대로53길 97 유진빌라 C동 3층 | R29: 반포하우스 | S29: =C29 -> F-1) (거실화) 오 | T29: 이승민 | U29: 국민 이승민 782702-04-131415 | V29: 010-7588-5201 | W29: 1974-11-04 | X29: =J29-500000 -> 1500000 | Y29: 이승민 | Z29: 엔코
A30: 강남구 | B30: 반포 | C30: G-1) 2인실 입구오 왼쪽 | D30: 2인실 | E30: 정세아 | F30: 46079 | G30: 46443 | J30: 2000000 | K30: 480000 | L30: 60000 | M30: =K30-L30 -> 420000 | N30: 100000 | O30: 051115- | P30: 010-2723-5526 | Q30: 서울시 서초구 사평대로53길 97 유진빌라 C동 3층 | R30: 반포하우스 | S30: =C30 -> G-1) 2인실 입구오 왼쪽 | T30: 이승민 | U30: 국민 이승민 782702-04-131415 | V30: 010-7588-5201 | W30: 1974-11-04 | X30: =J30-500000 -> 1500000 | Y30: 이승민 | Z30: 엔코
A31: 강남구 | B31: 반포 | C31: H-1) 2인실 입구오 오른쪽 | D31: 2인실 | E31: Eden Qazi | F31: 45931 | G31: 46112 | I31: 공실 | J31: 1000000 | K31: 480000 | L31: 0 | M31: =K31-L31 -> 480000 | N31: 100000 | P31: edenqazi.eq@gmail.com | Q31: 서울시 서초구 사평대로53길 97 유진빌라 C동 3층 | R31: 반포하우스 | S31: =C31 -> H-1) 2인실 입구오 오른쪽 | T31: 이승민 | U31: 국민은행 이승민 782702-04-131415 | V31: 010-7588-5201 | W31: 1974-11-04 | X31: =J31-500000 -> 500000 | Y31: 이승민
A32: 강남구 | B32: 반포 | C32: I-1) 2인실 왼 | D32: 2인실 | E32: 장원영 | F32: 45970 | G32: 46157 | J32: 2000000 | K32: 480000 | L32: 0 | M32: =K32-L32 -> 480000 | N32: 100000 | O32: 031202- | P32: 010-2502-4559 | Q32: 서울시 서초구 사평대로53길 97 유진빌라 C동 3층 | R32: 반포하우스 | S32: =C32 -> I-1) 2인실 왼 | T32: 이승민 | U32: 국민 이승민 782702-04-131415 | V32: 010-7588-5201 | W32: 1974-11-04 | X32: =J32-500000 -> 1500000 | Y32: 이승민
A33: 강남구 | B33: 반포 | C33: J-1) 2인실 오 | D33: 2인실 | E33: 이새롬 | F33: 45809 | G33: 46173 | J33: 1000000 | K33: 480000 | L33: 10000 | M33: =K33-L33 -> 470000 | N33: 100000 | O33: 880126- | P33: 010-2050-2037 | Q33: 서울시 서초구 사평대로53길 97 유진빌라 C동 3층 | R33: 반포하우스 | S33: =C33 -> J-1) 2인실 오 | T33: 이승민 | U33: 국민 이승민 782702-04-131415 | V33: 010-7588-5201 | W33: 1974-11-04 | X33: =J33-500000 -> 500000 | Y33: 이승민
A34: 강남구 | B34: 신사 | C34: A-1) 1인실 (베) 왼 | D34: 1인실 | E34: 이정연(Brooklyn) | F34: 46081 | G34: 46446 | J34: 2000000 | K34: 650000 | L34: 50000 | M34: =K34-L34 -> 600000 | N34: 100000 | O34: 669890141 | P34: 010-2400-6260 | Q34: 서울시 강남구 논현동 16-33 5층 501호 | R34: 신사하우스 | S34: =C34 -> A-1) 1인실 (베) 왼 | T34: 유재훈(곰곰쉐어) | U34: 카카오뱅크 유재훈 3333-30-2727013 | V34: 010-8682-8299 | W34: 1984-01-06 | X34: =J34-500000 -> 1500000
A35: 강남구 | B35: 신사 | C35: B-1) 1인실 (베) 오 | D35: 1인실 | E35: 황채원 | F35: 46075 | G35: 46255 | J35: 2000000 | K35: 650000 | L35: 0 | M35: =K35-L35 -> 650000 | N35: 100000 | O35: 000313- | P35: 010-8372-8901 | Q35: 서울시 강남구 논현동 16-33 5층 501호 | R35: 신사하우스 | S35: =C35 -> B-1) 1인실 (베) 오 | T35: 유재훈(곰곰쉐어) | U35: 카카오뱅크 유재훈 3333-30-2727013 | V35: 010-8682-8299 | W35: 1984-01-06 | X35: =J35-500000 -> 1500000
A36: 강남구 | B36: 신사 | C36: C-1) 1인실 거실 왼 | D36: 1인실 | E36: 진승연 | G36: 46123 | H36: 정상퇴실 4.11 | I36: 공실예정 | J36: 2000000 | K36: 620000 | L36: 0 | M36: =K36-L36 -> 620000 | N36: 100000 | P36: 010-7209-6001 | Q36: 서울시 강남구 논현동 16-33 5층 501호 | R36: 신사하우스 | S36: =C36 -> C-1) 1인실 거실 왼 | T36: 유재훈(곰곰쉐어) | U36: 카카오뱅크 유재훈 3333-30-2727013 | V36: 010-8682-8299 | W36: 1984-01-06 | X36: =J36-500000 -> 1500000
A37: 강남구 | B37: 신사 | C37: D-1) 1인실 거실 오 | D37: 1인실 | E37: Nguyen Gia Han(엔코) | F37: 46078 | G37: 46195 | J37: 2000000 | K37: 620000 | L37: -60000 | M37: =K37-L37 -> 680000 | N37: 100000 | Q37: 서울시 강남구 논현동 16-33 5층 501호 | R37: 신사하우스 | S37: =C37 -> D-1) 1인실 거실 오 | T37: 유재훈(곰곰쉐어) | U37: 카카오뱅크 유재훈 3333-30-2727013 | V37: 010-8682-8299 | W37: 1984-01-06 | X37: =J37-500000 -> 1500000
A38: 강남구 | B38: 신사 | C38: E-1) 1.5인실 왼 (행거) | D38: 2인실 | E38: 준오헤어 양재 1호점-김태희/구채민 | F38: 46026 | G38: 46206 | J38: 2000000 | K38: 520000 | M38: =K38-L38 -> 520000 | N38: 100000 | Q38: 서울시 강남구 논현동 16-33 5층 501호 | R38: 신사하우스 | S38: =C38 -> E-1) 1.5인실 왼 (행거) | T38: 유재훈(곰곰쉐어) | U38: 카카오뱅크 유재훈 3333-30-2727013 | V38: 010-8682-8299 | W38: 1984-01-06 | X38: =J38-500000 -> 1500000
A39: 강남구 | B39: 신사 | C39: E-2) 1.5인실 오 (붙) | D39: 2인실 | E39: 준오헤어 양재 1호점-윤서희 | F39: 46082 | G39: 46206 | J39: 2000000 | K39: 550000 | L39: 20000 | M39: =K39-L39 -> 530000 | N39: 100000 | P39: 010-3002-4782 | Q39: 서울시 강남구 논현동 16-33 5층 501호 | R39: 신사하우스 | S39: =C39 -> E-2) 1.5인실 오 (붙) | T39: 유재훈(곰곰쉐어) | U39: 카카오뱅크 유재훈 3333-30-2727013 | V39: 010-8682-8299 | W39: 1984-01-06 | X39: =J39-500000 -> 1500000 | Z39: 엔코
A40: 강남구 | B40: 신사 | C40: F-1) 2인실 왼 | D40: 2인실 | E40: 이리안(우주) | F40: 45979 | G40: 46343 | J40: 2000000 | K40: 480000 | L40: -48000 | M40: =K40-L40 -> 528000 | N40: 100000 | O40: 071007- | P40: 010-7284-6470 | Q40: 서울시 강남구 논현동 16-33 5층 501호 | R40: 신사하우스 | S40: =C40 -> F-1) 2인실 왼 | T40: 유재훈(곰곰쉐어) | U40: 카카오뱅크 유재훈 3333-30-2727013 | V40: 010-8682-8299 | W40: 1984-01-06 | X40: =J40-500000 -> 1500000 | Z40: 우주
...

Sheet 2026정산
B1: 하우스 | C1: 구분 | D1: 1월 이름 | E1: 1월 월세 | F1: 1 | G1: 2월 이름 | H1: 2월 월세 | I1: 2 | J1: 3월 이름 | K1: 3월 월세 | L1: 3 | M1: 4월 이름 | N1: 4월 월세 | O1: 4 | P1: 5월 이름 | Q1: 5월 월세 | R1: 5 | S1: 6월 이름 | T1: 6월 월세 | U1: 6 | V1: 7월 이름 | W1: 7월 월세 | X1: 7 | Y1: 8월 이름 | Z1: 8월 월세 | AA1: 8 | AB1: 9월 이름 | AC1: 9월 월세 | AD1: 9 | AE1: 10월 이름 | AF1: 10월 월세 | AG1: 10 | AH1: 11월 이름 | AI1: 11월 월세 | AJ1: 11 | AK1: 12월 이름 | AL1: 12월 월세 | AM1: 12 | AN1: 투자자
A2: 아띠 워너비 | B2: 워너비 | C2: ='입주자'!C5 -> A-1) 1인실 우측 | D2: BILLON Zoe | E2: 620000 | F2: 100000 | G2: BILLON Zoe 2/28 柯吟 周 Ko Yin Zhou (엔코) 2/28 | H2: 620000 | I2: 100000 | J2: 柯吟 周 Ko Yin Zhou (엔코) | K2: 680000 | L2: 100000 | M2: 柯吟 周 Ko Yin Zhou (엔코) | N2: 680000 | O2: 100000 | P2: 柯吟 周 Ko Yin Zhou (엔코) | Q2: 680000 | R2: 100000 | S2: 柯吟 周 Ko Yin Zhou (엔코) 6/22 | T2: 544024 | U2: 80000 | AN2: 강연수
A3: 아띠 워너비 | B3: 워너비(강남구 도산대로54길 48-15) | C3: ='입주자'!C6 -> B-1) 1인실 좌측 | D3: RAMADANTI ALFIYYAH ZAHRA 정아라 | E3: 590000 | F3: 100000 | G3: RAMADANTI ALFIYYAH ZAHRA 정아라 | H3: 590000 | I3: 100000 | J3: RAMADANTI ALFIYYAH ZAHRA 정아라 | K3: 590000 | L3: 100000 | M3: RAMADANTI ALFIYYAH ZAHRA 정아라 | N3: 590000 | O3: 100000 | P3: RAMADANTI ALFIYYAH ZAHRA 정아라 5/31 | Q3: 590000 | R3: 100000 | AN3: 강연수
A4: 아띠 워너비 | B4: 워너비 | C4: ='입주자'!C7 -> C-1) 2인실 오 | D4: 이은서 | E4: 470000 | F4: 100000 | G4: 이은서 | H4: 470000 | I4: 100000 | J4: 이은서 3/31 | K4: 470000 | L4: 100000 | M4: 유은선 4/1~30 | N4: 470000 | O4: 100000 | AN4: 강연수
A5: 아띠 워너비 | B5: 워너비 | C5: ='입주자'!C8 -> C-2) 2인실 왼 (창가) | D5: 한찬유 | E5: 470000 | F5: 100000 | G5: 한찬유 | H5: 470000 | I5: 100000 | J5: 한찬유 | K5: 470000 | L5: 100000 | M5: 한찬유 4/30 | N5: 470000 | O5: 100000 | AN5: 강연수
A6: 아띠 워너비 | C6: 합계 | E6: 2150000 | F6: 400000 | H6: =SUM(H2:H5) -> 2150000 | I6: =SUM(I2:I5) -> 400000 | K6: =SUM(K2:K5) -> 2210000 | L6: =SUM(L2:L5) -> 400000 | N6: =SUM(N2:N5) -> 2210000 | O6: =SUM(O2:O5) -> 400000 | Q6: =SUM(Q2:Q5) -> 1270000 | R6: =SUM(R2:R5) -> 200000 | T6: =SUM(T2:T5) -> 544024 | U6: =SUM(U2:U5) -> 80000 | W6: =SUM(W2:W5) -> 0 | X6: =SUM(X2:X5) -> 0 | Z6: =SUM(Z2:Z5) -> 0 | AA6: =SUM(AA2:AA5) -> 0 | AC6: =SUM(AC2:AC5) -> 0 | AD6: =SUM(AD2:AD5) -> 0 | AF6: =SUM(AF2:AF5) -> 0 | AG6: =SUM(AG2:AG5) -> 0 | AI6: =SUM(AI2:AI5) -> 0 | AJ6: =SUM(AJ2:AJ5) -> 0 | AL6: =SUM(AL2:AL5) -> 0 | AM6: =SUM(AM2:AM5) -> 0 | AN6: 강연수
A7: 아띠 워너비 | C7: (고정) 월세 | E7: 950000 | H7: 950000 | K7: 950000 | N7: 950000 | Q7: 950000 | T7: 950000 | W7: 950000 | Z7: 950000 | AC7: 950000 | AF7: 950000 | AI7: 950000 | AL7: 950000 | AN7: 강연수
A8: 아띠 워너비 | B8: 없음 | C8: (고정) 관리비 | F8: 없음 | I8: 없음 | L8: 0 | AN8: 강연수
A9: 아띠 워너비 | B9: 전기 01-0845-0159 | C9: (고정) 전기 | F9: 34060 | I9: 37920 | L9: 29860 | AN9: 강연수
A10: 아띠 워너비 | B10: 코원 23235558 | C10: (고정) 가스 | F10: 173590 | I10: 168070 | L10: 149340 | AN10: 강연수
A11: 아띠 워너비 | B11: 건물주 | C11: (고정) 수도 | F11: 60000 | G11: 예상 | I11: 60000 | J11: 예상 | L11: 60000 | AN11: 강연수
A12: 아띠 워너비 | C12: (고정) 인터넷 | F12: 22000 | I12: 22000 | L12: 22000 | O12: 22000 | R12: 22000 | U12: 22000 | X12: 22000 | AA12: 22000 | AD12: 22000 | AG12: 22000 | AJ12: 22000 | AM12: 22000 | AN12: 강연수
A13: 아띠 워너비 | C13: (고정) 정수기 | F13: 11000 | I13: 11000 | L13: 11000 | O13: 11000 | R13: 11000 | U13: 11000 | X13: 11000 | AA13: 11000 | AD13: 11000 | AG13: 11000 | AJ13: 11000 | AM13: 11000 | AN13: 강연수
A14: 아띠 워너비 | C14: 그외(청소/수리/쿠팡) | F14: =SUMIFS('지출'!$G$3:$G794,'지출'!$J$3:$J794,F$1,'지출'!$C$3:$C794,"워너비") -> 63550 | I14: =SUMIFS('지출'!$G$3:$G794,'지출'!$J$3:$J794,I$1,'지출'!$C$3:$C794,"워너비") -> 85750 | L14: =SUMIFS('지출'!$G$3:$G794,'지출'!$J$3:$J794,L$1,'지출'!$C$3:$C794,"워너비") -> 27020 | O14: =SUMIFS('지출'!$G$3:$G794,'지출'!$J$3:$J794,O$1,'지출'!$C$3:$C794,"워너비") -> 0 | R14: =SUMIFS('지출'!$G$3:$G794,'지출'!$J$3:$J794,R$1,'지출'!$C$3:$C794,"워너비") -> 0 | U14: =SUMIFS('지출'!$G$3:$G794,'지출'!$J$3:$J794,U$1,'지출'!$C$3:$C794,"워너비") -> 0 | X14: =SUMIFS('지출'!$G$3:$G794,'지출'!$J$3:$J794,X$1,'지출'!$C$3:$C794,"워너비") -> 0 | AA14: =SUMIFS('지출'!$G$3:$G794,'지출'!$J$3:$J794,AA$1,'지출'!$C$3:$C794,"워너비") -> 0 | AD14: =SUMIFS('지출'!$G$3:$G794,'지출'!$J$3:$J794,AD$1,'지출'!$C$3:$C794,"워너비") -> 0 | AG14: =SUMIFS('지출'!$G$3:$G794,'지출'!$J$3:$J794,AG$1,'지출'!$C$3:$C794,"워너비") -> 0 | AJ14: =SUMIFS('지출'!$G$3:$G794,'지출'!$J$3:$J794,AJ$1,'지출'!$C$3:$C794,"워너비") -> 0 | AM14: =SUMIFS('지출'!$G$3:$G794,'지출'!$J$3:$J794,AM$1,'지출'!$C$3:$C794,"워너비") -> 0 | AN14: 강연수
A15: 아띠 워너비 | C15: 순이익 | E15: =E6-(SUM(E7:E14)) -> 1200000 | F15: =F6-(SUM(F7:F14)) -> 35800 | H15: =H6-(SUM(H7:H14)) -> 1200000 | I15: =I6-(SUM(I7:I14)) -> 15260 | K15: =K6-(SUM(K7:K14)) -> 1260000 | L15: =L6-(SUM(L7:L14)) -> 100780 | N15: =N6-(SUM(N7:N14)) -> 1260000 | O15: =O6-(SUM(O7:O14)) -> 367000 | Q15: =Q6-(SUM(Q7:Q14)) -> 320000 | R15: =R6-(SUM(R7:R14)) -> 167000 | T15: =T6-(SUM(T7:T14)) -> -405976 | U15: =U6-(SUM(U7:U14)) -> 47000 | W15: =W6-(SUM(W7:W14)) -> -950000 | X15: =X6-(SUM(X7:X14)) -> -33000 | Z15: =Z6-(SUM(Z7:Z14)) -> -950000 | AA15: =AA6-(SUM(AA7:AA14)) -> -33000 | AC15: =AC6-(SUM(AC7:AC14)) -> -950000 | AD15: =AD6-(SUM(AD7:AD14)) -> -33000 | AF15: =AF6-(SUM(AF7:AF14)) -> -950000 | AG15: =AG6-(SUM(AG7:AG14)) -> -33000 | AI15: =AI6-(SUM(AI7:AI14)) -> -950000 | AJ15: =AJ6-(SUM(AJ7:AJ14)) -> -33000 | AL15: =AL6-(SUM(AL7:AL14)) -> -950000 | AM15: =AM6-(SUM(AM7:AM14)) -> -33000 | AN15: 강연수
A16: 아띠 워너비 | B16: 0 | C16: 투자자 | E16: =E15*$B16 -> 0 | H16: =H15*$B16 -> 0 | K16: =K15*$B16 -> 0 | N16: =N15*$B16 -> 0 | Q16: =Q15*$B16 -> 0 | T16: =T15*$B16 -> 0 | W16: =W15*$B16 -> 0 | Z16: =Z15*$B16 -> 0 | AC16: =AC15*$B16 -> 0 | AF16: =AF15*$B16 -> 0 | AI16: =AI15*$B16 -> 0 | AL16: =AL15*$B16 -> 0 | AN16: 강연수
A17: 아띠 워너비 | B17: 1 | C17: 운영자 | E17: =E15*$B17 -> 1200000 | H17: =H15*$B17 -> 1200000 | K17: =K15*$B17 -> 1260000 | N17: =N15*$B17 -> 1260000 | Q17: =Q15*$B17 -> 320000 | T17: =T15*$B17 -> -405976 | W17: =W15*$B17 -> -950000 | Z17: =Z15*$B17 -> -950000 | AC17: =AC15*$B17 -> -950000 | AF17: =AF15*$B17 -> -950000 | AI17: =AI15*$B17 -> -950000 | AL17: =AL15*$B17 -> -950000 | AN17: 강연수
A18: 영동 | B18: 영동 | C18: A-1) 화장실 옆 | D18: Maïa Redonnet(엔코) | E18: 700000 | F18: 100000 | G18: Maïa Redonnet(엔코) | H18: 700000 | I18: 100000 | J18: Maïa Redonnet(엔코) | K18: 700000 | L18: 100000 | M18: Maïa Redonnet(엔코) | N18: 700000 | O18: 100000 | P18: Maïa Redonnet(엔코) 5/31 | Q18: 700000 | R18: 100040 | AN18: 이승민
A19: 영동 | B19: 영동 | C19: B-1) 주방 앞 | D19: 헤바Heba(우주) | E19: 587400 | F19: 100000 | G19: 헤바Heba(우주) 2/28 Maria Katharina Henneken(엔코) 2/28 | H19: 587400 | I19: 100000 | J19: Maria Katharina Henneken(엔코) | K19: 700000 | L19: 100000 | M19: Maria Katharina Henneken(엔코) | N19: 700000 | O19: 100000 | P19: Maria Katharina Henneken(엔코) | Q19: 700000 | R19: 100000 | S19: Maria Katharina Henneken(엔코) 6/15 | T19: 395339 | U19: 58017 | AN19: 이승민
A20: 영동 | B20: 영동 | C20: C-1) 윗층 왼 | D20: 진승연 1/9 Adia Arthur(엔코) 1/9 | E20: =156774+460000 -> 616774 | F20: =29032+76682 -> 105714 | G20: Adia Arthur(엔코) | H20: 600000 | I20: 100000 | J20: Adia Arthur(엔코) | K20: 600000 | L20: 100000 | M20: Adia Arthur(엔코) | N20: 600000 | O20: 100000 | P20: Adia Arthur(엔코) | Q20: 600000 | R20: 100000 | S20: Adia Arthur(엔코) 6/27 | T20: 520000 | U20: 86684 | AN20: 이승민
A21: 영동 | B21: 영동 | C21: D-1) 윗층 오 | D21: 정다혜(우주) | E21: 507300 | F21: 100000 | G21: 정다혜(우주) | H21: 507300 | I21: 100000 | J21: 정다혜(우주) | K21: 507300 | L21: 100000 | M21: 정다혜(우주) | N21: 507300 | O21: 100000 | P21: 정다혜(우주) | Q21: 507300 | R21: 100000 | S21: 정다혜(우주) 6/30 | T21: 507300 | U21: 100000 | AN21: 이승민
A22: 영동 | B22: 영동 | C22: E-1) 화장실 우 오른쪽 | D22: Laurine BLANCHON(고고) 1/10 | E22: 154839 | F22: 32258 | G22: ★ | J22: ★ | AN22: 이승민
A23: 영동 | B23: 영동 | C23: E-2) 화장실 우 왼쪽 | D23: Cassandra BLANCHON(고고) 1/10 | E23: 154839 | F23: 32258 | G23: ★ | J23: ★ | AN23: 이승민
A24: 영동 | C24: 합계 | E24: =SUM(E18:E23) -> 2721152 | F24: =SUM(F18:F23) -> 470230 | H24: =SUM(H18:H23) -> 2394700 | I24: =SUM(I18:I23) -> 400000 | K24: =SUM(K18:K23) -> 2507300 | L24: =SUM(L18:L23) -> 400000 | N24: =SUM(N18:N23) -> 2507300 | O24: =SUM(O18:O23) -> 400000 | Q24: =SUM(Q18:Q23) -> 2507300 | R24: =SUM(R18:R23) -> 400040 | T24: =SUM(T18:T23) -> 1422639 | U24: =SUM(U18:U23) -> 244701 | W24: =SUM(W18:W23) -> 0 | X24: =SUM(X18:X23) -> 0 | Z24: =SUM(Z18:Z23) -> 0 | AA24: =SUM(AA18:AA23) -> 0 | AC24: =SUM(AC18:AC23) -> 0 | AD24: =SUM(AD18:AD23) -> 0 | AF24: =SUM(AF18:AF23) -> 0 | AG24: =SUM(AG18:AG23) -> 0 | AI24: =SUM(AI18:AI23) -> 0 | AJ24: =SUM(AJ18:AJ23) -> 0 | AL24: =SUM(AL18:AL23) -> 0 | AM24: =SUM(AM18:AM23) -> 0 | AN24: 이승민
A25: 영동 | C25: (고정) 월세 | E25: 1500000 | H25: 1500000 | K25: 1500000 | N25: 1500000 | Q25: 1500000 | T25: 1500000 | W25: 1500000 | Z25: 1500000 | AC25: 1500000 | AF25: 1500000 | AI25: 1500000 | AL25: 1500000 | AN25: 이승민
A26: 영동 | B26: 투자자고지 | C26: (고정) 관리비/계단 | F26: 70000 | I26: 70000 | L26: 70000 | O26: 70000 | R26: 70000 | U26: 70000 | X26: 70000 | AA26: 70000 | AD26: 70000 | AG26: 70000 | AJ26: 70000 | AM26: 70000 | AN26: 이승민
A27: 영동 | B27: 투자자고지 | C27: (고정) 전기 | F27: 139560 | I27: 130860 | J27: 예상 | L27: 135000 | AN27: 이승민
A28: 영동 | B28: 투자자고지 | C28: (고정) 가스 | F28: 411560 | I28: 370520 | J28: 예상 | L28: 400000 | AN28: 이승민
A29: 영동 | B29: 투자자고지 | C29: (고정) 수도 | F29: 40000 | I29: 40000 | L29: 45056 | R29: 80000 | AN29: 이승민
A30: 영동 | B30: 투자자고지 | C30: (고정) 인터넷 | F30: 22000 | I30: 22000 | L30: 22000 | O30: 22000 | R30: 22000 | U30: 22000 | X30: 22000 | AA30: 22000 | AD30: 22000 | AG30: 22000 | AJ30: 22000 | AM30: 22000 | AN30: 이승민
A31: 영동 | B31: 투자자고지 | C31: (고정) 정수기 | F31: 11000 | I31: 11000 | L31: 11000 | O31: 11000 | R31: 11000 | U31: 11000 | X31: 11000 | AA31: 11000 | AD31: 11000 | AG31: 11000 | AJ31: 11000 | AM31: 11000 | AN31: 이승민
A32: 영동 | C32: 그외(청소/수리/쿠팡) | F32: =SUMIFS('지출'!$G$3:$G794,'지출'!$J$3:$J794,F$1,'지출'!$C$3:$C794,"영동") -> 174360 | I32: =SUMIFS('지출'!$G$3:$G794,'지출'!$J$3:$J794,I$1,'지출'!$C$3:$C794,"영동") -> 50000 | L32: =SUMIFS('지출'!$G$3:$G794,'지출'!$J$3:$J794,L$1,'지출'!$C$3:$C794,"영동") -> 124500 | O32: =SUMIFS('지출'!$G$3:$G794,'지출'!$J$3:$J794,O$1,'지출'!$C$3:$C794,"영동") -> 0 | R32: =SUMIFS('지출'!$G$3:$G794,'지출'!$J$3:$J794,R$1,'지출'!$C$3:$C794,"영동") -> 0 | U32: =SUMIFS('지출'!$G$3:$G794,'지출'!$J$3:$J794,U$1,'지출'!$C$3:$C794,"영동") -> 0 | X32: =SUMIFS('지출'!$G$3:$G794,'지출'!$J$3:$J794,X$1,'지출'!$C$3:$C794,"영동") -> 0 | AA32: =SUMIFS('지출'!$G$3:$G794,'지출'!$J$3:$J794,AA$1,'지출'!$C$3:$C794,"영동") -> 0 | AD32: =SUMIFS('지출'!$G$3:$G794,'지출'!$J$3:$J794,AD$1,'지출'!$C$3:$C794,"영동") -> 0 | AG32: =SUMIFS('지출'!$G$3:$G794,'지출'!$J$3:$J794,AG$1,'지출'!$C$3:$C794,"영동") -> 0 | AJ32: =SUMIFS('지출'!$G$3:$G794,'지출'!$J$3:$J794,AJ$1,'지출'!$C$3:$C794,"영동") -> 0 | AM32: =SUMIFS('지출'!$G$3:$G794,'지출'!$J$3:$J794,AM$1,'지출'!$C$3:$C794,"영동") -> 0 | AN32: 이승민
A33: 영동 | C33: 순이익 | E33: =E24-(SUM(E25:E32)) -> 1221152 | F33: =F24-(SUM(F25:F32)) -> -398250 | H33: =H24-(SUM(H25:H32)) -> 894700 | I33: =I24-(SUM(I25:I32)) -> -294380 | K33: =K24-(SUM(K25:K32)) -> 1007300 | L33: =L24-(SUM(L25:L32)) -> -407556 | N33: =N24-(SUM(N25:N32)) -> 1007300 | O33: =O24-(SUM(O25:O32)) -> 297000 | Q33: =Q24-(SUM(Q25:Q32)) -> 1007300 | R33: =R24-(SUM(R25:R32)) -> 217040 | T33: =T24-(SUM(T25:T32)) -> -77361 | U33: =U24-(SUM(U25:U32)) -> 141701 | W33: =W24-(SUM(W25:W32)) -> -1500000 | X33: =X24-(SUM(X25:X32)) -> -103000 | Z33: =Z24-(SUM(Z25:Z32)) -> -1500000 | AA33: =AA24-(SUM(AA25:AA32)) -> -103000 | AC33: =AC24-(SUM(AC25:AC32)) -> -1500000 | AD33: =AD24-(SUM(AD25:AD32)) -> -103000 | AF33: =AF24-(SUM(AF25:AF32)) -> -1500000 | AG33: =AG24-(SUM(AG25:AG32)) -> -103000 | AI33: =AI24-(SUM(AI25:AI32)) -> -1500000 | AJ33: =AJ24-(SUM(AJ25:AJ32)) -> -103000 | AL33: =AL24-(SUM(AL25:AL32)) -> -1500000 | AM33: =AM24-(SUM(AM25:AM32)) -> -103000 | AN33: 이승민
A34: 영동 | B34: 0.7 | C34: 투자자 | E34: =E33*$B34 -> 854806.4 | H34: =H33*$B34 -> 626290 | K34: =K33*$B34 -> 705110 | N34: =N33*$B34 -> 705110 | Q34: =Q33*$B34 -> 705110 | T34: =T33*$B34 -> -54152.7 | W34: =W33*$B34 -> -1050000 | Z34: =Z33*$B34 -> -1050000 | AC34: =AC33*$B34 -> -1050000 | AF34: =AF33*$B34 -> -1050000 | AI34: =AI33*$B34 -> -1050000 | AL34: =AL33*$B34 -> -1050000 | AN34: 이승민
A35: 영동 | B35: 0.3 | C35: 운영자 | E35: =E33*$B35 -> 366345.6 | H35: =H33*$B35 -> 268410 | K35: =K33*$B35 -> 302190 | N35: =N33*$B35 -> 302190 | Q35: =Q33*$B35 -> 302190 | T35: =T33*$B35 -> -23208.3 | W35: =W33*$B35 -> -450000 | Z35: =Z33*$B35 -> -450000 | AC35: =AC33*$B35 -> -450000 | AF35: =AF33*$B35 -> -450000 | AI35: =AI33*$B35 -> -450000 | AL35: =AL33*$B35 -> -450000 | AN35: 이승민
A36: 삼중 | B36: 삼중 | C36: A-1) 미닫이문 오 | D36: 최예진 | E36: 550000 | F36: =100000+50000 -> 150000 | G36: 최예진 | H36: 550000 | I36: =100000 -> 100000 | J36: 최예진 | K36: 550000 | L36: 100000 | M36: 최예진 | N36: 550000 | O36: 100000 | P36: 최예진 | Q36: 550000 | R36: 100000 | S36: 최예진 | T36: 550000 | U36: 100000 | V36: 최예진 | W36: 550000 | X36: 100000 | Y36: 최예진 | Z36: 550000 | AA36: 100000 | AB36: 최예진 | AC36: 550000 | AD36: 100000 | AE36: 최예진 | AF36: 550000 | AG36: 100000 | AH36: 최예진 | AI36: 550000 | AJ36: 100000 | AK36: 최예진 | AL36: 550000 | AM36: 100000 | AN36: 이승민
A37: 삼중 | B37: 삼중 | C37: B-1) 거실 오른쪽 | D37: MOSSISA AYANTU TESHOME | E37: 620000 | F37: =100000+50000 -> 150000 | G37: MOSSISA AYANTU TESHOME | H37: 620000 | I37: =100000+85000 -> 185000 | J37: 차지수 3/21 | K37: 202258 | L37: 35484 | M37: 차지수 | N37: 570000 | O37: 100000 | P37: 차지수 | Q37: 570000 | R37: 100000 | S37: 차지수 | T37: 570000 | U37: 100000 | V37: 차지수 | W37: 570000 | X37: 100000 | Y37: 차지수 | Z37: 570000 | AA37: 100000 | AB37: 차지수 | AC37: 570000 | AD37: 100000 | AE37: 차지수 | AF37: 570000 | AG37: 100000 | AH37: 차지수 | AI37: 570000 | AJ37: 100000 | AK37: 차지수 | AL37: 570000 | AM37: 100000 | AN37: 이승민
A38: 삼중 | B38: 삼중 | C38: C-1) 주방 맞은편 | D38: 김유미나(엔코) | E38: 650000 | F38: =100000-55000+50000 -> 95000 | G38: 김유미나(엔코) | H38: 650000 | I38: =100000+85000 -> 185000 | J38: 김유미나 | K38: 480000 | L38: 77419 | M38: 김유미나 | N38: 620000 | O38: 100000 | P38: 김유미나 | Q38: 620000 | R38: 100000 | S38: 김유미나 6/7 | T38: 144667 | U38: 23333 | AN38: 이승민
A39: 삼중 | B39: 삼중 | C39: D-1) 주방 옆 문쪽 | D39: 신한나 1/31 | E39: 470000 | F39: 100000 | G39: ★ | J39: Dafne Carolina Castillo Normandía(고고) 3/15 | K39: 290645 | L39: 54839 | M39: Dafne Carolina Castillo Normandía(고고) | N39: 530000 | O39: 100000 | P39: Dafne Carolina Castillo Normandía(고고) | Q39: 530000 | R39: 100000 | S39: Dafne Carolina Castillo Normandía(고고) 6/14 | T39: 247333 | U39: 46667 | AN39: 이승민
A40: 삼중 | B40: 삼중 | C40: D-2) 주방 옆 안쪽 | D40: Gregoratti Greta(엔코) | E40: 550000 | F40: =100000+50000 -> 150000 | G40: Gregoratti Greta(엔코) | H40: =128333 -> 128333 | I40: =23343+85000 -> 108343 | J40: Gregoratti Greta(엔코) | K40: 550000 | L40: 100000 | M40: Gregoratti Greta(엔코) | N40: 550000 | O40: 100000 | P40: Gregoratti Greta(엔코) | Q40: 550000 | R40: 100000 | S40: Gregoratti Greta(엔코) | T40: 550000 | U40: 100000 | V40: Gregoratti Greta(엔코) | W40: 550000 | X40: 100000 | Y40: Gregoratti Greta(엔코) | Z40: 550000 | AA40: 100000 | AB40: Gregoratti Greta(엔코) | AC40: 550000 | AD40: 100000 | AE40: Gregoratti Greta(엔코) 10/24 | AF40: 128353 | AG40: 23323 | AN40: 이승민
...

Sheet 아띠 공과금
C57: 4771400
C59: 24년 10월부터 12월 : 4,771,400
C60: 2월까지 지불 완료

Sheet 지출
B2: 날짜 | C2: 지점 | D2: 종류 | E2: 지출내역 | F2: 수행 | G2: 금액 | H2: 1열 | I2: 2열 | J2: month | K2: Column 10
B3: 46023 | C3: 광흥 | D3: 수리 | E3: 비데수리 | F3: 원영훈 노비타 | G3: 25000 | J3: =MONTH(B3) -> 1
B4: 46023 | C4: 광흥 | D4: 쿠팡 | E4: 화장실청소세제 | F4: 강가경 | G4: 6930 | J4: =MONTH(B4) -> 1
B5: 46023 | C5: 반포 | D5: 쿠팡 | E5: 세탁세제 laundry detergent | F5: 서민지 | G5: 11900 | J5: =MONTH(B5) -> 1
B6: 46023 | C6: 영영1 | D6: 청소 | E6: 쓰레기봉투 garbage bag | F6: 최설화 | G6: 7400 | J6: =MONTH(B6) -> 1
B7: 46023 | C7: 동일 | D7: 쿠팡 | E7: 단열벽지 | G7: 53570 | J7: =MONTH(B7) -> 1
B8: 46025 | C8: 신촌 | D8: 청소 | E8: 주방세제, 휴지 | G8: 24590 | J8: =MONTH(B8) -> 1
B9: 46026 | C9: 소녀 | D9: 쿠팡 | E9: 고무장갑 Rubber glove, 수세미 Scrubbers | F9: 명주영 | G9: 10730 | J9: =MONTH(B9) -> 1
B10: 46026 | C10: 루프 | D10: 쿠팡 | E10: 휴지 tissue | F10: Jody | G10: 22250 | J10: =MONTH(B10) -> 1
B11: 46026 | C11: 샤네 | D11: 쿠팡 | E11: 욕실세제 | F11: 정하연 | G11: 6930 | J11: =MONTH(B11) -> 1
B12: 46027 | C12: 영동 | D12: 쿠팡 | E12: 휴지 | G12: 37340 | J12: =MONTH(B12) -> 1
B13: 46028 | C13: 반포 | D13: 쿠팡 | E13: 휴지 tissue | F13: 서민지 | G13: 22020 | J13: =MONTH(B13) -> 1
B14: 46023 | C14: 신사 | D14: 청소 | E14: 오늘수거 | G14: 7270 | J14: =MONTH(B14) -> 1
B15: 46023 | C15: 단짠 | D15: 청소 | E15: 오늘수거 | G15: 7600 | J15: =MONTH(B15) -> 1
B16: 46026 | C16: 시립 | D16: 청소 | E16: 오늘수거 | G16: 4880 | J16: =MONTH(B16) -> 1
B17: 46026 | C17: 아리 | D17: 청소 | E17: 오늘수거 | G17: 3760 | J17: =MONTH(B17) -> 1
B18: 46027 | C18: 숙녀 | D18: 청소 | E18: 오늘수거 | G18: 11040 | J18: =MONTH(B18) -> 1
B19: 46027 | C19: 대학 | D19: 청소 | E19: 오늘수거 | G19: 5160 | J19: =MONTH(B19) -> 1
B20: 46027 | C20: 영영2 | D20: 청소 | E20: 오늘수거 | G20: 6980 | J20: =MONTH(B20) -> 1
B21: 46027 | C21: 삼중 | D21: 청소 | E21: 오늘수거 | G21: 12720 | J21: =MONTH(B21) -> 1
B22: 46028 | C22: 숙녀 | D22: 청소 | E22: 오늘수거 | G22: 10760 | J22: =MONTH(B22) -> 1
B23: 46028 | C23: 브루 | D23: 청소 | E23: 오늘수거 | G23: 6420 | J23: =MONTH(B23) -> 1
B24: 46028 | C24: 영동 | D24: 청소 | E24: 오늘수거 | G24: 4880 | J24: =MONTH(B24) -> 1
B25: 46028 | C25: 동동 | D25: 쿠팡 | E25: 고무장갑 Rubber glove, 수세미 Scrubbers, 청소 밀대 Cleaning mop | F25: 김정민 | G25: 21720 | J25: =MONTH(B25) -> 1
B26: 46030 | C26: 신촌 | D26: 청소 | E26: 쓰레기봉투 | F26: YASUI AYANE | G26: 3800 | J26: =MONTH(B26) -> 1
B27: 46030 | C27: 와이지 | D27: 쿠팡 | E27: 주방세제 kitchen detergent | F27: Nguyen Ngoc Tram | G27: 2340 | J27: =MONTH(B27) -> 1
B28: 46030 | C28: 영영2 | D28: 청소 | E28: 건조기 폐기 | G28: 0 | H28: 환불 | J28: =MONTH(B28) -> 1
B29: 46031 | C29: 당산 | D29: 쿠팡 | E29: 결로방지페인트 | G29: 13600 | J29: =MONTH(B29) -> 1
B30: 46032 | C30: 소녀 | D30: 쿠팡 | E30: 휴지 | F30: 오유정 | G30: 22020 | J30: =MONTH(B30) -> 1
B31: 46032 | C31: 샛별 | D31: 쿠팡 | E31: 건전지 | G31: 15900 | J31: =MONTH(B31) -> 1
B32: 46032 | C32: 동일 | D32: 쿠팡 | E32: 건전지 | G32: 15900 | J32: =MONTH(B32) -> 1
B33: 46033 | C33: 당산 | D33: 쿠팡 | E33: 휴지 tissue, 세탁세제 laundry detergent, 주방세제 kitchen detergent | F33: 박진민 | G33: 36260 | J33: =MONTH(B33) -> 1
B34: 46033 | C34: 한성 | D34: 쿠팡 | E34: 주방세제 kitchen detergent, 청소 밀대 Cleaning mop, 수세미 Scrubbers | F34: Elisa Libert | G34: 18660 | J34: =MONTH(B34) -> 1
B35: 46033 | C35: 선릉 | D35: 청소 | E35: 쓰레기봉투 garbage bag | F35: 권민경 | G35: 2500 | J35: =MONTH(B35) -> 1
B36: 46034 | C36: 반포 | D36: 투어 | E36: 투어페이백 | G36: 30000 | J36: =MONTH(B36) -> 1
B37: 46035 | C37: 소녀 | D37: 청소 | E37: 소파 테이블 폐기 | F37: 성북구청 | G37: 16000 | J37: =MONTH(B37) -> 1
B38: 46035 | C38: 선릉 | D38: 쿠팡 | E38: 세탁세제 laundry detergent, 주방세제 kitchen detergent, 휴지 tissue, 수세미 Scrubbers, 청소 밀대 Cleaning mop, 락스 | F38: Fulvia Verna | G38: =52580-11490 -> 41090 | H38: 청소밀대 반품 | J38: =MONTH(B38) -> 1
